Workbook

Sheet Readme
B3: Spreadsheet giving details about the various input parameters used in the ITHIM Global run for Bogotá, note that any distribution parameters used for running ITHIM-Global in sampling mode are omitted
B5: blue cells | C5: contain formula
B6: green cells | C6: need manual filling in
B10: Tab name | C10: Description
B11: all_city_parameter_inputs | C11: Table detailing all the city specific parameters which are read in during an ITHIM-Global run
B12: All_city_list | C12: List of all city specific parameters including their source and and explanation of what the parameter does. Takes its values from all_city_parameter_inputs and Default tabs. Parameter explanations and sources are added manually. To add a new city, add the city to the all_city_parameter_inputs tab (new column) and copy down the blue cells of the last populated row. If the structure of all_city_parameter_inputs is changed, i.e. if parameters are added or deleted, add or delete rows for all cities to ensure the parameter descriptions and references are still in line with the correct parameter. The input values from all_city_parameter_inputs are currently being read based on their row and column value.
B13: all_global_parameter_inputs | C13: Details the global parameters, used as input file for ITHIM runs.
B14: All_global_list | C14: Details the values of the global parameters, i.e. the values that are not city specific. Reads values from all_global_parameter_inputs tab and Default tab and gives further information of where these values come from.
B15: Default | C15: List default values for all parameters, parameter explanations added to this tab are used in All_city_list
B16: Further_input_files | C16: Details where the additional input files needed for an ITHIM run can be found within the ITHIM-Global R package
B17: Grouped_sources | C17: Lookup table that shows from which city input parameter information on the all_city_list tab can be copied for other cities
B18: Lookup | C18: table linking different parameter names and classifications
B19: Safety in Numbers | C19: Details how the safety in numbers parameters were derived
B23: Document history
B24: version | C24: Changes made | D24: Author | E24: Date
B25: v0.1 | C25: Initial set-up based on InputParameters_v35.1 | D25: AKS | E25: 45175
B26: v1.0 | C26: Changed the retirement ages of bus, truck and commercial motorcycle drivers | D26: AKS | E26: 45272
B27: v1.01 | C27: update MET values for light activity | D27: LT | E27: 21/03/2024
B28: v1.02 | C28: update CO2 from EDGAR database. The values come from: https://github.com/ITHIM/CO2_EDGAR_2018/blob/main/output/CO2_2018_ALL_cities.csv | D28: AA | E28: 45455
B29: v2.0 | C29: Removed backround_pa_confidence, PM_emissions_confidence and CO2_emissions_confidence parameter values as not needed for constant model run, updated cycling MET source, set minimum_pt_time to 5 | D29: AKS | E29: 45484
B30: v2.1 | C30: Introduced a new parameter called TREAT_TAXI_AS_CAR, which treats taxis as cars (and essentially adds taxi's distance to car/car_driver) | D30: AA | E30: 45488
B31: v2.2 | C31: Set TREAT_TAXI_AS_CAR to FALSE | D31: AA | E31: 45489
B32: v3.0 | C32: updated the SIN coefficients using the random effects values from the meta analysis | D32: AKS | E32: 45491
B33: v3.1 | C33: Replaced big_truck with heavy_truck | D33: AA | E33: 45495
B34: v3.2 | C34: Set auto_rickshaw speed to 4, same as default speed in model | D34: AKS | E34: 45496
B35: v3.3 | C35: Updated references | D35: AKS | E35: 45496
B36: v3.4 | C36: added TREAT_TAXI_AS_CAR parameter to entire spreadsheet | D36: AKS | E36: 45531
B37: v4.0 | C37: converted MET to MMET input parameters | D37: AKS | E37: 45539

Sheet all_city_parameter_inputs
B1: 欧洲和亚洲我把没有typology城市的数据删掉了 | C1: 南美洲 | P1: 北美洲 | AV1: 大洋洲 | BC1: 非洲 | BY1: 欧洲 | DT1: 亚洲
A2: parameter | B2: detail | C2: bogota | D2: Brasilia | E2: Santiago | F2: Lima | G2: La Paz | H2: Quito | I2: Asuncion | J2: Caracas | K2: Medellin | L2: Buenos Aires | M2: Montevideo | N2: Sao Paulo | O2: Panama City | P2: Mexico City | Q2: New York | R2: Chicago | S2: San Francisco | T2: Los Angeles | U2: Ottawa | V2: Vancouver | W2: Montreal | X2: Toronto | Y2: Boston | Z2: Washington | AA2: Detroit | AB2: Atlanta | AC2: Philadelphia | AD2: Miami | AE2: Dallas-Fort Worth | AF2: Seattle | AG2: Las Vegas | AH2: New Orleans | AI2: Nashville-Davidson | AJ2: Salt Lake City | AK2: Denver-Aurora | AL2: Phoenix-Mesa | AM2: Oklahoma City | AN2: Charlotte | AO2: Pittsburgh | AP2: Baltimore | AQ2: Santo Domingo | AR2: San Salvador | AS2: Havana | AT2: San Juan | AU2: Guatemala City | AV2: Sydney | AW2: Melbourne | AX2: Brisbane | AY2: Perth | AZ2: Canberra | BA2: Wellington | BB2: Auckland | BC2: Cairo | BD2: Algiers | BE2: Accra | BF2: Cape Town | BG2: Nairobi | BH2: Kigali | BI2: Lagos | BJ2: Kano | BK2: Addis Ababa | BL2: Rabat | BM2: Casablanca | BN2: Luanda | BO2: Dar es Salaam | BP2: Kinshasa | BQ2: Khartoum | BR2: Mogadishu | BS2: Tripoli | BT2: N'Djamena | BU2: Maputo | BV2: Abidjan | BW2: Tunis | BX2: Johannesburg | BY2: Warsaw | BZ2: Milan | CA2: London | CB2: Manchester | CC2: Glasgow | CD2: Copenhagen | CE2: Vienna | CF2: Brussels | CG2: Antwerp | CH2: Lisboa | CI2: Athens | CJ2: Dublin | CK2: Helsinki | CL2: Stockholm | CM2: Budapest | CN2: Bratislava | CO2: Sofia | CP2: Bucharest | CQ2: Moscow | CR2: Paris | CS2: Marseille | CT2: Lyon | CU2: Lille | CV2: Bordeaux | CW2: Toulouse | CX2: Nice | CY2: Birmingham | CZ2: Berlin | DA2: Hamburg | DB2: Munich | DC2: Frankfurt | DD2: Rome | DE2: Naples | DF2: Turin | DG2: Madrid | DH2: Valencia | DI2: Barcelona | DJ2: Zurich | DK2: Amsterdam | DL2: Rotterdam | DM2: Prague | DN2: St. Petersburg | DO2: Kazan | DP2: Belgrade | DQ2: Kiev | DR2: Odessa | DS2: Oslo | DT2: Nanjing | DU2: Hangzhou | DV2: Jinan | DW2: Changsha | DX2: Kunming | DY2: Xian | DZ2: Ningbo | EA2: Wuxi | EB2: Qingdao | EC2: Beijingb (km/hour) | ED2: Shijiazhuang | EE2: Taiyuan | EF2: Changchun | EG2: Urumqi | EH2: Wuhan | EI2: Nagoya | EJ2: Osaka | EK2: Singapore | EL2: Tehran | EM2: Riyadh | EN2: Hanoi | EO2: Manila | EP2: Kuala Lumpur | EQ2: Jakarta | ER2: Bangkok | ES2: Jerusalem | ET2: Shanghai | EU2: Shenzhen | EV2: Guangzhou | EW2: Mumbai | EX2: NEW DELHI | EY2: Bangalore | EZ2: Tokyo | FA2: Seoul | FB2: Zhengzhou | FC2: Kabul | FD2: Tbilisi | FE2: Baku | FF2: Dhaka | FG2: Istanbul | FH2: Ankara | FI2: Almaty | FJ2: Bishkek | FK2: Tashkent | FL2: Ulaanbaatar | FM2: Abu Dhabi | FN2: Sharjah | FO2: Dubai | FP2: Kuwait City | FQ2: Amman | FR2: Damascus | FS2: Beirut | FT2: Rangoon | FU2: Kathmandu | FV2: Kolkata | FW2: Jaipur | FX2: Chennai | FY2: Congqing | FZ2: Pyongyang | GA2: Taipei | GB2: Karachi | GC2: Busan | GD2: Sapporo | GE2: Yerevan | GF2: Hong Kong
A3: speeds (单位是km/hour) | B3: auto_rickshaw | C3: 4 | E3: 4 | K3: 4 | L3: 4 | M3: 4 | N3: 4 | O3: 4 | P3: 4 | BE3: 4 | BF3: 4 | BG3: 4 | EX3: 4 | EY3: 4
B4: bus | C4: 8.1 | E4: 8.1 | K4: 8.1 | L4: 8.1 | M4: 8.1 | N4: 8.1 | O4: 8.1 | P4: 8.1 | Q4: 13.2 | R4: 16.1 | BE4: 12 | BF4: 12 | BG4: 12 | ET4: 17.6 | EX4: 12 | EY4: 12
B5: car | C5: 13.8 | E5: 13.8 | K5: 13.8 | L5: 13.8 | M5: 13.8 | N5: 13.8 | O5: 13.8 | P5: 13.8 | Q5: 24.1 | R5: 17.7 | BE5: 15 | BF5: 15 | BG5: 15 | EX5: 15 | EY5: 15
B6: cycle | C6: 7.2 | E6: 8.4 | K6: 8.4 | L6: 8.4 | M6: 8.4 | N6: 7.2 | O6: 7.2 | P6: 7.2 | Q6: 14.5 | R6: 22.7 | BE6: 6 | BF6: 6 | BG6: 6 | ET6: 13.4 | EX6: 6 | EY6: 6
B7: subway | C7: 18.1 | E7: 18.1 | K7: 18.1 | L7: 18.1 | M7: 18.1 | N7: 18.1 | O7: 18.1 | P7: 18.1 | Q7: 28 | R7: 88.5
B8: motorcycle | C8: 15.2 | E8: 18.4 | K8: 18.4 | L8: 18.4 | M8: 18.4 | N8: 15.2 | O8: 15.2 | P8: 15.2 | BE8: 15 | BF8: 15 | BG8: 15 | ET8: 22.5 | EX8: 15 | EY8: 15
B9: other | C9: 9.1 | E9: 9.1 | K9: 9.1 | L9: 9.1 | M9: 9.1 | N9: 9.1 | O9: 9.1 | P9: 9.1
B10: pedestrian | C10: 2.5 | E10: 3 | K10: 3 | L10: 3 | M10: 3 | N10: 2.5 | O10: 2.5 | P10: 2.5 | Q10: 5.5 | R10: 4.8 | BE10: 2 | BF10: 2 | BG10: 2 | EX10: 2 | EY10: 2
B11: rail | C11: 21.9 | E11: 23.2 | K11: 23.2 | L11: 23.2 | M11: 23.2 | N11: 21.9 | O11: 21.9 | P11: 21.9 | Q11: 82.1 | R11: 91.7 | BE11: 20.6 | BF11: 20.6 | BG11: 20.6 | EX11: 20.6 | EY11: 20.6
B12: taxi | C12: 12.56 | E12: 13.1 | K12: 13.1 | L12: 13.1 | M12: 13.1 | N12: 12.56 | O12: 12.56 | P12: 12.56 | Q12: 19.3 | R12: =R5 -> 17.7 | BE12: 12 | BF12: 12 | BG12: 12 | EX12: 12 | EY12: 12
B13: truck | C13: 8.1 | E13: 8.1 | K13: 8.1 | L13: 8.1 | M13: 8.1 | N13: 8.1 | O13: 8.1 | P13: 8.1 | Q13: 88.5 | R13: 85.7 | BE13: 12 | BF13: 12 | BG13: 12 | EC13: =(80+100)/2 -> 90 | EX13: 12 | EY13: 12
B14: van | C14: 13.8 | E14: 13.8 | K14: 13.8 | L14: 13.8 | M14: 13.8 | N14: 13.8 | O14: 13.8 | P14: 13.8 | BE14: 15 | BF14: 15 | BG14: 15 | EX14: 15 | EY14: 15
A15: PM_emission_inventories | B15: motorcycle | C15: 0.0023031654
B16: car | C16: 0.081980353
B17: bus_driver | C17: 0.12246677
B18: heavy_truck | C18: 0.45445404
B19: truck | C19: 0.33879567
B20: van | C20: 0
B21: other | C21: 0
B22: taxi | C22: 0
B23: auto_rickshaw | C23: 0
A24: injury_reporting_rate | B24: constant | C24: 0.8982419 | D24: 0.8982419
B25: alpha
B26: beta
A27: chronic_disease_scalar | B27: constant | C27: 1 | D27: 1
B28: mean
B29: sd
A30: pm_conc_base (from Edgar) | B30: constant | C30: 12.69
B31: mean
B32: sd
A33: pm_trans_share (emission ) | B33: constant | C33: 0.42
B34: alpha
B35: beta
A36: background_pa_scalar | B36: constant | C36: 1 | D36: 1
B37: mean
B38: sd
A39: bus_walk_time (average walk to bus time) | B39: constant | C39: 16
B40: mean
...

Sheet All_city_list
A1: List of parameters found in all_city_parameter_inputs | L1: Values that have been entered manually
L2: Values read in from other locations
A3: Location column | B3: Row location | C3: Default lookup | D3: Grouped sources lookup | E3: Location | F3: Parameter | G3: Detail | H3: Value | I3: Default value | J3: Classification | K3: Description | L3: Location of data (e.g. in v-drive, web link) | M3: Source of data | N3: Comments
A4: 3 | B4: 2 | C4: =IF(G4 = "",F4,IF(OR(G4="alpha",G4="beta",G4="constant",G4="sd",G4="mean",G4="sample"),F4,F4&" "&G4)) -> parameter detail | D4: =F4&"_"&E4 -> parameter_南美洲 | E4: {=INDIRECT(ADDRESS(1,A4,1,1,"all_city_parameter_inputs"))} -> 南美洲 | F4: {=IF(AND(ISBLANK(INDIRECT(ADDRESS(B4,2,1,1,"all_city_parameter_inputs"))), ISBLANK(INDIRECT(ADDRESS(B4,1,1,1,"all_city_parameter_inputs")))), "", IF(ISBLANK(INDIRECT(ADDRESS(B4,1,1,1,"all_city_parameter_inputs"))), All_city_list!F3,INDIRECT(ADDRESS(B4,1,1,1,"all_city_parameter_inputs"))))} -> parameter | G4: {=IF(AND(ISBLANK(INDIRECT(ADDRESS(B4,3,1,1,"all_city_parameter_inputs"))),ISBLANK(INDIRECT(ADDRESS(B4,2,1,1,"all_city_parameter_inputs")))),"",IF(ISBLANK(INDIRECT(ADDRESS(B4,2,1,1,"all_city_parameter_inputs"))),"",INDIRECT(ADDRESS(B4,2,1,1,"all_city_parameter_inputs"))))} -> detail | H4: {=IF(ISBLANK(INDIRECT(ADDRESS(B4,A4,1,1,"all_city_parameter_inputs"))), "--",INDIRECT(ADDRESS(B4,A4,1,1,"all_city_parameter_inputs")))} -> bogota | I4: =IF(OR(G4="alpha",G4="beta",G4="sd",G4="mean"),"--",VLOOKUP(C4,Default!$B$5:$H$114,7,FALSE)) -> #N/A | J4: =VLOOKUP(F4,Lookup!$C$5:$D$110,2, FALSE) -> #N/A | K4: =VLOOKUP(C4,Default!$B$4:$E$114,4, FALSE) -> #N/A | M4: average speeds between London and Delhi travel surveys and where the speeds for Delhi are higher than those for London, the London speeds are chosen
A5: 3 | B5: 3 | C5: =IF(G5 = "",F5,IF(OR(G5="alpha",G5="beta",G5="constant",G5="sd",G5="mean",G5="sample"),F5,F5&" "&G5)) -> speeds (单位是km/hour) auto_rickshaw | D5: =F5&"_"&E5 -> speeds (单位是km/hour)_南美洲 | E5: {=INDIRECT(ADDRESS(1,A5,1,1,"all_city_parameter_inputs"))} -> 南美洲 | F5: {=IF(AND(ISBLANK(INDIRECT(ADDRESS(B5,2,1,1,"all_city_parameter_inputs"))), ISBLANK(INDIRECT(ADDRESS(B5,1,1,1,"all_city_parameter_inputs")))), "", IF(ISBLANK(INDIRECT(ADDRESS(B5,1,1,1,"all_city_parameter_inputs"))), All_city_list!F4,INDIRECT(ADDRESS(B5,1,1,1,"all_city_parameter_inputs"))))} -> speeds (单位是km/hour) | G5: {=IF(AND(ISBLANK(INDIRECT(ADDRESS(B5,3,1,1,"all_city_parameter_inputs"))),ISBLANK(INDIRECT(ADDRESS(B5,2,1,1,"all_city_parameter_inputs")))),"",IF(ISBLANK(INDIRECT(ADDRESS(B5,2,1,1,"all_city_parameter_inputs"))),"",INDIRECT(ADDRESS(B5,2,1,1,"all_city_parameter_inputs"))))} -> auto_rickshaw | H5: {=IF(ISBLANK(INDIRECT(ADDRESS(B5,A5,1,1,"all_city_parameter_inputs"))), "--",INDIRECT(ADDRESS(B5,A5,1,1,"all_city_parameter_inputs")))} -> 4 | I5: =IF(OR(G5="alpha",G5="beta",G5="sd",G5="mean"),"--",VLOOKUP(C5,Default!$B$5:$H$114,7,FALSE)) -> #N/A | J5: =VLOOKUP(F5,Lookup!$C$5:$D$110,2, FALSE) -> #N/A | K5: =VLOOKUP(C5,Default!$B$4:$E$114,4, FALSE) -> #N/A | L5: {=IF(ISNA(VLOOKUP($D5,Grouped_Sources!$C:$C,1,FALSE)),"", INDIRECT(VLOOKUP($D5,Grouped_Sources!$C:$I,5,FALSE)))} | M5: {=IF(ISNA(VLOOKUP($D5,Grouped_Sources!$C:$C,1,FALSE)),"", INDIRECT(VLOOKUP($D5,Grouped_Sources!$C:$I,6,FALSE)))} | N5: {=IF(ISNA(VLOOKUP($D5,Grouped_Sources!$C:$C,1,FALSE)),"", INDIRECT(VLOOKUP($D5,Grouped_Sources!$C:$I,7,FALSE)))}
A6: 3 | B6: 4 | C6: =IF(G6 = "",F6,IF(OR(G6="alpha",G6="beta",G6="constant",G6="sd",G6="mean",G6="sample"),F6,F6&" "&G6)) -> speeds (单位是km/hour) bus | D6: =F6&"_"&E6 -> speeds (单位是km/hour)_南美洲 | E6: {=INDIRECT(ADDRESS(1,A6,1,1,"all_city_parameter_inputs"))} -> 南美洲 | F6: {=IF(AND(ISBLANK(INDIRECT(ADDRESS(B6,2,1,1,"all_city_parameter_inputs"))), ISBLANK(INDIRECT(ADDRESS(B6,1,1,1,"all_city_parameter_inputs")))), "", IF(ISBLANK(INDIRECT(ADDRESS(B6,1,1,1,"all_city_parameter_inputs"))), All_city_list!F5,INDIRECT(ADDRESS(B6,1,1,1,"all_city_parameter_inputs"))))} -> speeds (单位是km/hour) | G6: {=IF(AND(ISBLANK(INDIRECT(ADDRESS(B6,3,1,1,"all_city_parameter_inputs"))),ISBLANK(INDIRECT(ADDRESS(B6,2,1,1,"all_city_parameter_inputs")))),"",IF(ISBLANK(INDIRECT(ADDRESS(B6,2,1,1,"all_city_parameter_inputs"))),"",INDIRECT(ADDRESS(B6,2,1,1,"all_city_parameter_inputs"))))} -> bus | H6: {=IF(ISBLANK(INDIRECT(ADDRESS(B6,A6,1,1,"all_city_parameter_inputs"))), "--",INDIRECT(ADDRESS(B6,A6,1,1,"all_city_parameter_inputs")))} -> 8.1 | I6: =IF(OR(G6="alpha",G6="beta",G6="sd",G6="mean"),"--",VLOOKUP(C6,Default!$B$5:$H$114,7,FALSE)) -> #N/A | J6: =VLOOKUP(F6,Lookup!$C$5:$D$110,2, FALSE) -> #N/A | K6: =VLOOKUP(C6,Default!$B$4:$E$114,4, FALSE) -> #N/A | L6: {=IF(ISNA(VLOOKUP($D6,Grouped_Sources!$C:$C,1,FALSE)),"", INDIRECT(VLOOKUP($D6,Grouped_Sources!$C:$I,5,FALSE)))} | M6: {=IF(ISNA(VLOOKUP($D6,Grouped_Sources!$C:$C,1,FALSE)),"", INDIRECT(VLOOKUP($D6,Grouped_Sources!$C:$I,6,FALSE)))} | N6: {=IF(ISNA(VLOOKUP($D6,Grouped_Sources!$C:$C,1,FALSE)),"", INDIRECT(VLOOKUP($D6,Grouped_Sources!$C:$I,7,FALSE)))}
A7: 3 | B7: 5 | C7: =IF(G7 = "",F7,IF(OR(G7="alpha",G7="beta",G7="constant",G7="sd",G7="mean",G7="sample"),F7,F7&" "&G7)) -> speeds (单位是km/hour) car | D7: =F7&"_"&E7 -> speeds (单位是km/hour)_南美洲 | E7: {=INDIRECT(ADDRESS(1,A7,1,1,"all_city_parameter_inputs"))} -> 南美洲 | F7: {=IF(AND(ISBLANK(INDIRECT(ADDRESS(B7,2,1,1,"all_city_parameter_inputs"))), ISBLANK(INDIRECT(ADDRESS(B7,1,1,1,"all_city_parameter_inputs")))), "", IF(ISBLANK(INDIRECT(ADDRESS(B7,1,1,1,"all_city_parameter_inputs"))), All_city_list!F6,INDIRECT(ADDRESS(B7,1,1,1,"all_city_parameter_inputs"))))} -> speeds (单位是km/hour) | G7: {=IF(AND(ISBLANK(INDIRECT(ADDRESS(B7,3,1,1,"all_city_parameter_inputs"))),ISBLANK(INDIRECT(ADDRESS(B7,2,1,1,"all_city_parameter_inputs")))),"",IF(ISBLANK(INDIRECT(ADDRESS(B7,2,1,1,"all_city_parameter_inputs"))),"",INDIRECT(ADDRESS(B7,2,1,1,"all_city_parameter_inputs"))))} -> car | H7: {=IF(ISBLANK(INDIRECT(ADDRESS(B7,A7,1,1,"all_city_parameter_inputs"))), "--",INDIRECT(ADDRESS(B7,A7,1,1,"all_city_parameter_inputs")))} -> 13.8 | I7: =IF(OR(G7="alpha",G7="beta",G7="sd",G7="mean"),"--",VLOOKUP(C7,Default!$B$5:$H$114,7,FALSE)) -> #N/A | J7: =VLOOKUP(F7,Lookup!$C$5:$D$110,2, FALSE) -> #N/A | K7: =VLOOKUP(C7,Default!$B$4:$E$114,4, FALSE) -> #N/A | L7: {=IF(ISNA(VLOOKUP($D7,Grouped_Sources!$C:$C,1,FALSE)),"", INDIRECT(VLOOKUP($D7,Grouped_Sources!$C:$I,5,FALSE)))} | M7: {=IF(ISNA(VLOOKUP($D7,Grouped_Sources!$C:$C,1,FALSE)),"", INDIRECT(VLOOKUP($D7,Grouped_Sources!$C:$I,6,FALSE)))} | N7: {=IF(ISNA(VLOOKUP($D7,Grouped_Sources!$C:$C,1,FALSE)),"", INDIRECT(VLOOKUP($D7,Grouped_Sources!$C:$I,7,FALSE)))}
A8: 3 | B8: 6 | C8: =IF(G8 = "",F8,IF(OR(G8="alpha",G8="beta",G8="constant",G8="sd",G8="mean",G8="sample"),F8,F8&" "&G8)) -> speeds (单位是km/hour) cycle | D8: =F8&"_"&E8 -> speeds (单位是km/hour)_南美洲 | E8: {=INDIRECT(ADDRESS(1,A8,1,1,"all_city_parameter_inputs"))} -> 南美洲 | F8: {=IF(AND(ISBLANK(INDIRECT(ADDRESS(B8,2,1,1,"all_city_parameter_inputs"))), ISBLANK(INDIRECT(ADDRESS(B8,1,1,1,"all_city_parameter_inputs")))), "", IF(ISBLANK(INDIRECT(ADDRESS(B8,1,1,1,"all_city_parameter_inputs"))), All_city_list!F7,INDIRECT(ADDRESS(B8,1,1,1,"all_city_parameter_inputs"))))} -> speeds (单位是km/hour) | G8: {=IF(AND(ISBLANK(INDIRECT(ADDRESS(B8,3,1,1,"all_city_parameter_inputs"))),ISBLANK(INDIRECT(ADDRESS(B8,2,1,1,"all_city_parameter_inputs")))),"",IF(ISBLANK(INDIRECT(ADDRESS(B8,2,1,1,"all_city_parameter_inputs"))),"",INDIRECT(ADDRESS(B8,2,1,1,"all_city_parameter_inputs"))))} -> cycle | H8: {=IF(ISBLANK(INDIRECT(ADDRESS(B8,A8,1,1,"all_city_parameter_inputs"))), "--",INDIRECT(ADDRESS(B8,A8,1,1,"all_city_parameter_inputs")))} -> 7.2 | I8: =IF(OR(G8="alpha",G8="beta",G8="sd",G8="mean"),"--",VLOOKUP(C8,Default!$B$5:$H$114,7,FALSE)) -> #N/A | J8: =VLOOKUP(F8,Lookup!$C$5:$D$110,2, FALSE) -> #N/A | K8: =VLOOKUP(C8,Default!$B$4:$E$114,4, FALSE) -> #N/A | L8: {=IF(ISNA(VLOOKUP($D8,Grouped_Sources!$C:$C,1,FALSE)),"", INDIRECT(VLOOKUP($D8,Grouped_Sources!$C:$I,5,FALSE)))} | M8: {=IF(ISNA(VLOOKUP($D8,Grouped_Sources!$C:$C,1,FALSE)),"", INDIRECT(VLOOKUP($D8,Grouped_Sources!$C:$I,6,FALSE)))} | N8: {=IF(ISNA(VLOOKUP($D8,Grouped_Sources!$C:$C,1,FALSE)),"", INDIRECT(VLOOKUP($D8,Grouped_Sources!$C:$I,7,FALSE)))}
A9: 3 | B9: 7 | C9: =IF(G9 = "",F9,IF(OR(G9="alpha",G9="beta",G9="constant",G9="sd",G9="mean",G9="sample"),F9,F9&" "&G9)) -> speeds (单位是km/hour) subway | D9: =F9&"_"&E9 -> speeds (单位是km/hour)_南美洲 | E9: {=INDIRECT(ADDRESS(1,A9,1,1,"all_city_parameter_inputs"))} -> 南美洲 | F9: {=IF(AND(ISBLANK(INDIRECT(ADDRESS(B9,2,1,1,"all_city_parameter_inputs"))), ISBLANK(INDIRECT(ADDRESS(B9,1,1,1,"all_city_parameter_inputs")))), "", IF(ISBLANK(INDIRECT(ADDRESS(B9,1,1,1,"all_city_parameter_inputs"))), All_city_list!F8,INDIRECT(ADDRESS(B9,1,1,1,"all_city_parameter_inputs"))))} -> speeds (单位是km/hour) | G9: {=IF(AND(ISBLANK(INDIRECT(ADDRESS(B9,3,1,1,"all_city_parameter_inputs"))),ISBLANK(INDIRECT(ADDRESS(B9,2,1,1,"all_city_parameter_inputs")))),"",IF(ISBLANK(INDIRECT(ADDRESS(B9,2,1,1,"all_city_parameter_inputs"))),"",INDIRECT(ADDRESS(B9,2,1,1,"all_city_parameter_inputs"))))} -> subway | H9: {=IF(ISBLANK(INDIRECT(ADDRESS(B9,A9,1,1,"all_city_parameter_inputs"))), "--",INDIRECT(ADDRESS(B9,A9,1,1,"all_city_parameter_inputs")))} -> 18.1 | I9: =IF(OR(G9="alpha",G9="beta",G9="sd",G9="mean"),"--",VLOOKUP(C9,Default!$B$5:$H$114,7,FALSE)) -> #N/A | J9: =VLOOKUP(F9,Lookup!$C$5:$D$110,2, FALSE) -> #N/A | K9: =VLOOKUP(C9,Default!$B$4:$E$114,4, FALSE) -> #N/A | L9: {=IF(ISNA(VLOOKUP($D9,Grouped_Sources!$C:$C,1,FALSE)),"", INDIRECT(VLOOKUP($D9,Grouped_Sources!$C:$I,5,FALSE)))} | M9: {=IF(ISNA(VLOOKUP($D9,Grouped_Sources!$C:$C,1,FALSE)),"", INDIRECT(VLOOKUP($D9,Grouped_Sources!$C:$I,6,FALSE)))} | N9: {=IF(ISNA(VLOOKUP($D9,Grouped_Sources!$C:$C,1,FALSE)),"", INDIRECT(VLOOKUP($D9,Grouped_Sources!$C:$I,7,FALSE)))}
A10: 3 | B10: 8 | C10: =IF(G10 = "",F10,IF(OR(G10="alpha",G10="beta",G10="constant",G10="sd",G10="mean",G10="sample"),F10,F10&" "&G10)) -> speeds (单位是km/hour) motorcycle | D10: =F10&"_"&E10 -> speeds (单位是km/hour)_南美洲 | E10: {=INDIRECT(ADDRESS(1,A10,1,1,"all_city_parameter_inputs"))} -> 南美洲 | F10: {=IF(AND(ISBLANK(INDIRECT(ADDRESS(B10,2,1,1,"all_city_parameter_inputs"))), ISBLANK(INDIRECT(ADDRESS(B10,1,1,1,"all_city_parameter_inputs")))), "", IF(ISBLANK(INDIRECT(ADDRESS(B10,1,1,1,"all_city_parameter_inputs"))), All_city_list!F9,INDIRECT(ADDRESS(B10,1,1,1,"all_city_parameter_inputs"))))} -> speeds (单位是km/hour) | G10: {=IF(AND(ISBLANK(INDIRECT(ADDRESS(B10,3,1,1,"all_city_parameter_inputs"))),ISBLANK(INDIRECT(ADDRESS(B10,2,1,1,"all_city_parameter_inputs")))),"",IF(ISBLANK(INDIRECT(ADDRESS(B10,2,1,1,"all_city_parameter_inputs"))),"",INDIRECT(ADDRESS(B10,2,1,1,"all_city_parameter_inputs"))))} -> motorcycle | H10: {=IF(ISBLANK(INDIRECT(ADDRESS(B10,A10,1,1,"all_city_parameter_inputs"))), "--",INDIRECT(ADDRESS(B10,A10,1,1,"all_city_parameter_inputs")))} -> 15.2 | I10: =IF(OR(G10="alpha",G10="beta",G10="sd",G10="mean"),"--",VLOOKUP(C10,Default!$B$5:$H$114,7,FALSE)) -> #N/A | J10: =VLOOKUP(F10,Lookup!$C$5:$D$110,2, FALSE) -> #N/A | K10: =VLOOKUP(C10,Default!$B$4:$E$114,4, FALSE) -> #N/A | L10: {=IF(ISNA(VLOOKUP($D10,Grouped_Sources!$C:$C,1,FALSE)),"", INDIRECT(VLOOKUP($D10,Grouped_Sources!$C:$I,5,FALSE)))} | M10: {=IF(ISNA(VLOOKUP($D10,Grouped_Sources!$C:$C,1,FALSE)),"", INDIRECT(VLOOKUP($D10,Grouped_Sources!$C:$I,6,FALSE)))} | N10: {=IF(ISNA(VLOOKUP($D10,Grouped_Sources!$C:$C,1,FALSE)),"", INDIRECT(VLOOKUP($D10,Grouped_Sources!$C:$I,7,FALSE)))}
A11: 3 | B11: 9 | C11: =IF(G11 = "",F11,IF(OR(G11="alpha",G11="beta",G11="constant",G11="sd",G11="mean",G11="sample"),F11,F11&" "&G11)) -> speeds (单位是km/hour) other | D11: =F11&"_"&E11 -> speeds (单位是km/hour)_南美洲 | E11: {=INDIRECT(ADDRESS(1,A11,1,1,"all_city_parameter_inputs"))} -> 南美洲 | F11: {=IF(AND(ISBLANK(INDIRECT(ADDRESS(B11,2,1,1,"all_city_parameter_inputs"))), ISBLANK(INDIRECT(ADDRESS(B11,1,1,1,"all_city_parameter_inputs")))), "", IF(ISBLANK(INDIRECT(ADDRESS(B11,1,1,1,"all_city_parameter_inputs"))), All_city_list!F10,INDIRECT(ADDRESS(B11,1,1,1,"all_city_parameter_inputs"))))} -> speeds (单位是km/hour) | G11: {=IF(AND(ISBLANK(INDIRECT(ADDRESS(B11,3,1,1,"all_city_parameter_inputs"))),ISBLANK(INDIRECT(ADDRESS(B11,2,1,1,"all_city_parameter_inputs")))),"",IF(ISBLANK(INDIRECT(ADDRESS(B11,2,1,1,"all_city_parameter_inputs"))),"",INDIRECT(ADDRESS(B11,2,1,1,"all_city_parameter_inputs"))))} -> other | H11: {=IF(ISBLANK(INDIRECT(ADDRESS(B11,A11,1,1,"all_city_parameter_inputs"))), "--",INDIRECT(ADDRESS(B11,A11,1,1,"all_city_parameter_inputs")))} -> 9.1 | I11: =IF(OR(G11="alpha",G11="beta",G11="sd",G11="mean"),"--",VLOOKUP(C11,Default!$B$5:$H$114,7,FALSE)) -> #N/A | J11: =VLOOKUP(F11,Lookup!$C$5:$D$110,2, FALSE) -> #N/A | K11: =VLOOKUP(C11,Default!$B$4:$E$114,4, FALSE) -> #N/A | L11: {=IF(ISNA(VLOOKUP($D11,Grouped_Sources!$C:$C,1,FALSE)),"", INDIRECT(VLOOKUP($D11,Grouped_Sources!$C:$I,5,FALSE)))} | M11: {=IF(ISNA(VLOOKUP($D11,Grouped_Sources!$C:$C,1,FALSE)),"", INDIRECT(VLOOKUP($D11,Grouped_Sources!$C:$I,6,FALSE)))} | N11: {=IF(ISNA(VLOOKUP($D11,Grouped_Sources!$C:$C,1,FALSE)),"", INDIRECT(VLOOKUP($D11,Grouped_Sources!$C:$I,7,FALSE)))}
A12: 3 | B12: 10 | C12: =IF(G12 = "",F12,IF(OR(G12="alpha",G12="beta",G12="constant",G12="sd",G12="mean",G12="sample"),F12,F12&" "&G12)) -> speeds (单位是km/hour) pedestrian | D12: =F12&"_"&E12 -> speeds (单位是km/hour)_南美洲 | E12: {=INDIRECT(ADDRESS(1,A12,1,1,"all_city_parameter_inputs"))} -> 南美洲 | F12: {=IF(AND(ISBLANK(INDIRECT(ADDRESS(B12,2,1,1,"all_city_parameter_inputs"))), ISBLANK(INDIRECT(ADDRESS(B12,1,1,1,"all_city_parameter_inputs")))), "", IF(ISBLANK(INDIRECT(ADDRESS(B12,1,1,1,"all_city_parameter_inputs"))), All_city_list!F11,INDIRECT(ADDRESS(B12,1,1,1,"all_city_parameter_inputs"))))} -> speeds (单位是km/hour) | G12: {=IF(AND(ISBLANK(INDIRECT(ADDRESS(B12,3,1,1,"all_city_parameter_inputs"))),ISBLANK(INDIRECT(ADDRESS(B12,2,1,1,"all_city_parameter_inputs")))),"",IF(ISBLANK(INDIRECT(ADDRESS(B12,2,1,1,"all_city_parameter_inputs"))),"",INDIRECT(ADDRESS(B12,2,1,1,"all_city_parameter_inputs"))))} -> pedestrian | H12: {=IF(ISBLANK(INDIRECT(ADDRESS(B12,A12,1,1,"all_city_parameter_inputs"))), "--",INDIRECT(ADDRESS(B12,A12,1,1,"all_city_parameter_inputs")))} -> 2.5 | I12: =IF(OR(G12="alpha",G12="beta",G12="sd",G12="mean"),"--",VLOOKUP(C12,Default!$B$5:$H$114,7,FALSE)) -> #N/A | J12: =VLOOKUP(F12,Lookup!$C$5:$D$110,2, FALSE) -> #N/A | K12: =VLOOKUP(C12,Default!$B$4:$E$114,4, FALSE) -> #N/A | L12: {=IF(ISNA(VLOOKUP($D12,Grouped_Sources!$C:$C,1,FALSE)),"", INDIRECT(VLOOKUP($D12,Grouped_Sources!$C:$I,5,FALSE)))} | M12: {=IF(ISNA(VLOOKUP($D12,Grouped_Sources!$C:$C,1,FALSE)),"", INDIRECT(VLOOKUP($D12,Grouped_Sources!$C:$I,6,FALSE)))} | N12: {=IF(ISNA(VLOOKUP($D12,Grouped_Sources!$C:$C,1,FALSE)),"", INDIRECT(VLOOKUP($D12,Grouped_Sources!$C:$I,7,FALSE)))}
A13: 3 | B13: 11 | C13: =IF(G13 = "",F13,IF(OR(G13="alpha",G13="beta",G13="constant",G13="sd",G13="mean",G13="sample"),F13,F13&" "&G13)) -> speeds (单位是km/hour) rail | D13: =F13&"_"&E13 -> speeds (单位是km/hour)_南美洲 | E13: {=INDIRECT(ADDRESS(1,A13,1,1,"all_city_parameter_inputs"))} -> 南美洲 | F13: {=IF(AND(ISBLANK(INDIRECT(ADDRESS(B13,2,1,1,"all_city_parameter_inputs"))), ISBLANK(INDIRECT(ADDRESS(B13,1,1,1,"all_city_parameter_inputs")))), "", IF(ISBLANK(INDIRECT(ADDRESS(B13,1,1,1,"all_city_parameter_inputs"))), All_city_list!F12,INDIRECT(ADDRESS(B13,1,1,1,"all_city_parameter_inputs"))))} -> speeds (单位是km/hour) | G13: {=IF(AND(ISBLANK(INDIRECT(ADDRESS(B13,3,1,1,"all_city_parameter_inputs"))),ISBLANK(INDIRECT(ADDRESS(B13,2,1,1,"all_city_parameter_inputs")))),"",IF(ISBLANK(INDIRECT(ADDRESS(B13,2,1,1,"all_city_parameter_inputs"))),"",INDIRECT(ADDRESS(B13,2,1,1,"all_city_parameter_inputs"))))} -> rail | H13: {=IF(ISBLANK(INDIRECT(ADDRESS(B13,A13,1,1,"all_city_parameter_inputs"))), "--",INDIRECT(ADDRESS(B13,A13,1,1,"all_city_parameter_inputs")))} -> 21.9 | I13: =IF(OR(G13="alpha",G13="beta",G13="sd",G13="mean"),"--",VLOOKUP(C13,Default!$B$5:$H$114,7,FALSE)) -> #N/A | J13: =VLOOKUP(F13,Lookup!$C$5:$D$110,2, FALSE) -> #N/A | K13: =VLOOKUP(C13,Default!$B$4:$E$114,4, FALSE) -> #N/A | L13: {=IF(ISNA(VLOOKUP($D13,Grouped_Sources!$C:$C,1,FALSE)),"", INDIRECT(VLOOKUP($D13,Grouped_Sources!$C:$I,5,FALSE)))} | M13: {=IF(ISNA(VLOOKUP($D13,Grouped_Sources!$C:$C,1,FALSE)),"", INDIRECT(VLOOKUP($D13,Grouped_Sources!$C:$I,6,FALSE)))} | N13: {=IF(ISNA(VLOOKUP($D13,Grouped_Sources!$C:$C,1,FALSE)),"", INDIRECT(VLOOKUP($D13,Grouped_Sources!$C:$I,7,FALSE)))}
A14: 3 | B14: 12 | C14: =IF(G14 = "",F14,IF(OR(G14="alpha",G14="beta",G14="constant",G14="sd",G14="mean",G14="sample"),F14,F14&" "&G14)) -> speeds (单位是km/hour) taxi | D14: =F14&"_"&E14 -> speeds (单位是km/hour)_南美洲 | E14: {=INDIRECT(ADDRESS(1,A14,1,1,"all_city_parameter_inputs"))} -> 南美洲 | F14: {=IF(AND(ISBLANK(INDIRECT(ADDRESS(B14,2,1,1,"all_city_parameter_inputs"))), ISBLANK(INDIRECT(ADDRESS(B14,1,1,1,"all_city_parameter_inputs")))), "", IF(ISBLANK(INDIRECT(ADDRESS(B14,1,1,1,"all_city_parameter_inputs"))), All_city_list!F13,INDIRECT(ADDRESS(B14,1,1,1,"all_city_parameter_inputs"))))} -> speeds (单位是km/hour) | G14: {=IF(AND(ISBLANK(INDIRECT(ADDRESS(B14,3,1,1,"all_city_parameter_inputs"))),ISBLANK(INDIRECT(ADDRESS(B14,2,1,1,"all_city_parameter_inputs")))),"",IF(ISBLANK(INDIRECT(ADDRESS(B14,2,1,1,"all_city_parameter_inputs"))),"",INDIRECT(ADDRESS(B14,2,1,1,"all_city_parameter_inputs"))))} -> taxi | H14: {=IF(ISBLANK(INDIRECT(ADDRESS(B14,A14,1,1,"all_city_parameter_inputs"))), "--",INDIRECT(ADDRESS(B14,A14,1,1,"all_city_parameter_inputs")))} -> 12.56 | I14: =IF(OR(G14="alpha",G14="beta",G14="sd",G14="mean"),"--",VLOOKUP(C14,Default!$B$5:$H$114,7,FALSE)) -> #N/A | J14: =VLOOKUP(F14,Lookup!$C$5:$D$110,2, FALSE) -> #N/A | K14: =VLOOKUP(C14,Default!$B$4:$E$114,4, FALSE) -> #N/A | L14: {=IF(ISNA(VLOOKUP($D14,Grouped_Sources!$C:$C,1,FALSE)),"", INDIRECT(VLOOKUP($D14,Grouped_Sources!$C:$I,5,FALSE)))} | M14: {=IF(ISNA(VLOOKUP($D14,Grouped_Sources!$C:$C,1,FALSE)),"", INDIRECT(VLOOKUP($D14,Grouped_Sources!$C:$I,6,FALSE)))} | N14: {=IF(ISNA(VLOOKUP($D14,Grouped_Sources!$C:$C,1,FALSE)),"", INDIRECT(VLOOKUP($D14,Grouped_Sources!$C:$I,7,FALSE)))}
A15: 3 | B15: 13 | C15: =IF(G15 = "",F15,IF(OR(G15="alpha",G15="beta",G15="constant",G15="sd",G15="mean",G15="sample"),F15,F15&" "&G15)) -> speeds (单位是km/hour) truck | D15: =F15&"_"&E15 -> speeds (单位是km/hour)_南美洲 | E15: {=INDIRECT(ADDRESS(1,A15,1,1,"all_city_parameter_inputs"))} -> 南美洲 | F15: {=IF(AND(ISBLANK(INDIRECT(ADDRESS(B15,2,1,1,"all_city_parameter_inputs"))), ISBLANK(INDIRECT(ADDRESS(B15,1,1,1,"all_city_parameter_inputs")))), "", IF(ISBLANK(INDIRECT(ADDRESS(B15,1,1,1,"all_city_parameter_inputs"))), All_city_list!F14,INDIRECT(ADDRESS(B15,1,1,1,"all_city_parameter_inputs"))))} -> speeds (单位是km/hour) | G15: {=IF(AND(ISBLANK(INDIRECT(ADDRESS(B15,3,1,1,"all_city_parameter_inputs"))),ISBLANK(INDIRECT(ADDRESS(B15,2,1,1,"all_city_parameter_inputs")))),"",IF(ISBLANK(INDIRECT(ADDRESS(B15,2,1,1,"all_city_parameter_inputs"))),"",INDIRECT(ADDRESS(B15,2,1,1,"all_city_parameter_inputs"))))} -> truck | H15: {=IF(ISBLANK(INDIRECT(ADDRESS(B15,A15,1,1,"all_city_parameter_inputs"))), "--",INDIRECT(ADDRESS(B15,A15,1,1,"all_city_parameter_inputs")))} -> 8.1 | I15: =IF(OR(G15="alpha",G15="beta",G15="sd",G15="mean"),"--",VLOOKUP(C15,Default!$B$5:$H$114,7,FALSE)) -> #N/A | J15: =VLOOKUP(F15,Lookup!$C$5:$D$110,2, FALSE) -> #N/A | K15: =VLOOKUP(C15,Default!$B$4:$E$114,4, FALSE) -> #N/A | L15: {=IF(ISNA(VLOOKUP($D15,Grouped_Sources!$C:$C,1,FALSE)),"", INDIRECT(VLOOKUP($D15,Grouped_Sources!$C:$I,5,FALSE)))} | M15: {=IF(ISNA(VLOOKUP($D15,Grouped_Sources!$C:$C,1,FALSE)),"", INDIRECT(VLOOKUP($D15,Grouped_Sources!$C:$I,6,FALSE)))} | N15: {=IF(ISNA(VLOOKUP($D15,Grouped_Sources!$C:$C,1,FALSE)),"", INDIRECT(VLOOKUP($D15,Grouped_Sources!$C:$I,7,FALSE)))}
A16: 3 | B16: 14 | C16: =IF(G16 = "",F16,IF(OR(G16="alpha",G16="beta",G16="constant",G16="sd",G16="mean",G16="sample"),F16,F16&" "&G16)) -> speeds (单位是km/hour) van | D16: =F16&"_"&E16 -> speeds (单位是km/hour)_南美洲 | E16: {=INDIRECT(ADDRESS(1,A16,1,1,"all_city_parameter_inputs"))} -> 南美洲 | F16: {=IF(AND(ISBLANK(INDIRECT(ADDRESS(B16,2,1,1,"all_city_parameter_inputs"))), ISBLANK(INDIRECT(ADDRESS(B16,1,1,1,"all_city_parameter_inputs")))), "", IF(ISBLANK(INDIRECT(ADDRESS(B16,1,1,1,"all_city_parameter_inputs"))), All_city_list!F5,INDIRECT(ADDRESS(B16,1,1,1,"all_city_parameter_inputs"))))} -> speeds (单位是km/hour) | G16: {=IF(AND(ISBLANK(INDIRECT(ADDRESS(B16,3,1,1,"all_city_parameter_inputs"))),ISBLANK(INDIRECT(ADDRESS(B16,2,1,1,"all_city_parameter_inputs")))),"",IF(ISBLANK(INDIRECT(ADDRESS(B16,2,1,1,"all_city_parameter_inputs"))),"",INDIRECT(ADDRESS(B16,2,1,1,"all_city_parameter_inputs"))))} -> van | H16: {=IF(ISBLANK(INDIRECT(ADDRESS(B16,A16,1,1,"all_city_parameter_inputs"))), "--",INDIRECT(ADDRESS(B16,A16,1,1,"all_city_parameter_inputs")))} -> 13.8 | I16: =IF(OR(G16="alpha",G16="beta",G16="sd",G16="mean"),"--",VLOOKUP(C16,Default!$B$5:$H$114,7,FALSE)) -> #N/A | J16: =VLOOKUP(F16,Lookup!$C$5:$D$110,2, FALSE) -> #N/A | K16: =VLOOKUP(C16,Default!$B$4:$E$114,4, FALSE) -> #N/A | L16: https://edgar.jrc.ec.europa.eu/, obtained values based on private correspondence | M16: EDGAR, 2018
A17: 3 | B17: 15 | C17: =IF(G17 = "",F17,IF(OR(G17="alpha",G17="beta",G17="constant",G17="sd",G17="mean",G17="sample"),F17,F17&" "&G17)) -> PM_emission_inventories motorcycle | D17: =F17&"_"&E17 -> PM_emission_inventories_南美洲 | E17: {=INDIRECT(ADDRESS(1,A17,1,1,"all_city_parameter_inputs"))} -> 南美洲 | F17: {=IF(AND(ISBLANK(INDIRECT(ADDRESS(B17,2,1,1,"all_city_parameter_inputs"))), ISBLANK(INDIRECT(ADDRESS(B17,1,1,1,"all_city_parameter_inputs")))), "", IF(ISBLANK(INDIRECT(ADDRESS(B17,1,1,1,"all_city_parameter_inputs"))), All_city_list!F16,INDIRECT(ADDRESS(B17,1,1,1,"all_city_parameter_inputs"))))} -> PM_emission_inventories | G17: {=IF(AND(ISBLANK(INDIRECT(ADDRESS(B17,3,1,1,"all_city_parameter_inputs"))),ISBLANK(INDIRECT(ADDRESS(B17,2,1,1,"all_city_parameter_inputs")))),"",IF(ISBLANK(INDIRECT(ADDRESS(B17,2,1,1,"all_city_parameter_inputs"))),"",INDIRECT(ADDRESS(B17,2,1,1,"all_city_parameter_inputs"))))} -> motorcycle | H17: {=IF(ISBLANK(INDIRECT(ADDRESS(B17,A17,1,1,"all_city_parameter_inputs"))), "--",INDIRECT(ADDRESS(B17,A17,1,1,"all_city_parameter_inputs")))} -> 0.0023031654 | I17: =IF(OR(G17="alpha",G17="beta",G17="sd",G17="mean"),"--",VLOOKUP(C17,Default!$B$5:$H$114,7,FALSE)) -> 0.0023031654 | J17: =VLOOKUP(F17,Lookup!$C$5:$D$110,2, FALSE) -> Pollution values | K17: =VLOOKUP(C17,Default!$B$4:$E$114,4, FALSE) -> - Used to estimate the PM for scenarios (function "scenario_pm_calculations"). - used as reference to compute confidence around it (function "ithim_setup_parameters"). - used to create VEHICLE_INVENTORY, with speeds, PM and CO2 emissions (function "set_vehicle_inventory"). | L17: {=IF(ISNA(VLOOKUP($D17,Grouped_Sources!$C:$C,1,FALSE)),"", INDIRECT(VLOOKUP($D17,Grouped_Sources!$C:$I,5,FALSE)))} | M17: {=IF(ISNA(VLOOKUP($D17,Grouped_Sources!$C:$C,1,FALSE)),"", INDIRECT(VLOOKUP($D17,Grouped_Sources!$C:$I,6,FALSE)))} | N17: {=IF(ISNA(VLOOKUP($D17,Grouped_Sources!$C:$C,1,FALSE)),"", INDIRECT(VLOOKUP($D17,Grouped_Sources!$C:$I,7,FALSE)))}
A18: 3 | B18: 16 | C18: =IF(G18 = "",F18,IF(OR(G18="alpha",G18="beta",G18="constant",G18="sd",G18="mean",G18="sample"),F18,F18&" "&G18)) -> PM_emission_inventories car | D18: =F18&"_"&E18 -> PM_emission_inventories_南美洲 | E18: {=INDIRECT(ADDRESS(1,A18,1,1,"all_city_parameter_inputs"))} -> 南美洲 | F18: {=IF(AND(ISBLANK(INDIRECT(ADDRESS(B18,2,1,1,"all_city_parameter_inputs"))), ISBLANK(INDIRECT(ADDRESS(B18,1,1,1,"all_city_parameter_inputs")))), "", IF(ISBLANK(INDIRECT(ADDRESS(B18,1,1,1,"all_city_parameter_inputs"))), All_city_list!F17,INDIRECT(ADDRESS(B18,1,1,1,"all_city_parameter_inputs"))))} -> PM_emission_inventories | G18: {=IF(AND(ISBLANK(INDIRECT(ADDRESS(B18,3,1,1,"all_city_parameter_inputs"))),ISBLANK(INDIRECT(ADDRESS(B18,2,1,1,"all_city_parameter_inputs")))),"",IF(ISBLANK(INDIRECT(ADDRESS(B18,2,1,1,"all_city_parameter_inputs"))),"",INDIRECT(ADDRESS(B18,2,1,1,"all_city_parameter_inputs"))))} -> car | H18: {=IF(ISBLANK(INDIRECT(ADDRESS(B18,A18,1,1,"all_city_parameter_inputs"))), "--",INDIRECT(ADDRESS(B18,A18,1,1,"all_city_parameter_inputs")))} -> 0.081980353 | I18: =IF(OR(G18="alpha",G18="beta",G18="sd",G18="mean"),"--",VLOOKUP(C18,Default!$B$5:$H$114,7,FALSE)) -> 0.081980353 | J18: =VLOOKUP(F18,Lookup!$C$5:$D$110,2, FALSE) -> Pollution values | K18: =VLOOKUP(C18,Default!$B$4:$E$114,4, FALSE) -> 0 | L18: {=IF(ISNA(VLOOKUP($D18,Grouped_Sources!$C:$C,1,FALSE)),"", INDIRECT(VLOOKUP($D18,Grouped_Sources!$C:$I,5,FALSE)))} | M18: {=IF(ISNA(VLOOKUP($D18,Grouped_Sources!$C:$C,1,FALSE)),"", INDIRECT(VLOOKUP($D18,Grouped_Sources!$C:$I,6,FALSE)))} | N18: {=IF(ISNA(VLOOKUP($D18,Grouped_Sources!$C:$C,1,FALSE)),"", INDIRECT(VLOOKUP($D18,Grouped_Sources!$C:$I,7,FALSE)))}
A19: 3 | B19: 17 | C19: =IF(G19 = "",F19,IF(OR(G19="alpha",G19="beta",G19="constant",G19="sd",G19="mean",G19="sample"),F19,F19&" "&G19)) -> PM_emission_inventories bus_driver | D19: =F19&"_"&E19 -> PM_emission_inventories_南美洲 | E19: {=INDIRECT(ADDRESS(1,A19,1,1,"all_city_parameter_inputs"))} -> 南美洲 | F19: {=IF(AND(ISBLANK(INDIRECT(ADDRESS(B19,2,1,1,"all_city_parameter_inputs"))), ISBLANK(INDIRECT(ADDRESS(B19,1,1,1,"all_city_parameter_inputs")))), "", IF(ISBLANK(INDIRECT(ADDRESS(B19,1,1,1,"all_city_parameter_inputs"))), All_city_list!F18,INDIRECT(ADDRESS(B19,1,1,1,"all_city_parameter_inputs"))))} -> PM_emission_inventories | G19: {=IF(AND(ISBLANK(INDIRECT(ADDRESS(B19,3,1,1,"all_city_parameter_inputs"))),ISBLANK(INDIRECT(ADDRESS(B19,2,1,1,"all_city_parameter_inputs")))),"",IF(ISBLANK(INDIRECT(ADDRESS(B19,2,1,1,"all_city_parameter_inputs"))),"",INDIRECT(ADDRESS(B19,2,1,1,"all_city_parameter_inputs"))))} -> bus_driver | H19: {=IF(ISBLANK(INDIRECT(ADDRESS(B19,A19,1,1,"all_city_parameter_inputs"))), "--",INDIRECT(ADDRESS(B19,A19,1,1,"all_city_parameter_inputs")))} -> 0.12246677 | I19: =IF(OR(G19="alpha",G19="beta",G19="sd",G19="mean"),"--",VLOOKUP(C19,Default!$B$5:$H$114,7,FALSE)) -> 0.12246677 | J19: =VLOOKUP(F19,Lookup!$C$5:$D$110,2, FALSE) -> Pollution values | K19: =VLOOKUP(C19,Default!$B$4:$E$114,4, FALSE) -> 0 | L19: {=IF(ISNA(VLOOKUP($D19,Grouped_Sources!$C:$C,1,FALSE)),"", INDIRECT(VLOOKUP($D19,Grouped_Sources!$C:$I,5,FALSE)))} | M19: {=IF(ISNA(VLOOKUP($D19,Grouped_Sources!$C:$C,1,FALSE)),"", INDIRECT(VLOOKUP($D19,Grouped_Sources!$C:$I,6,FALSE)))} | N19: {=IF(ISNA(VLOOKUP($D19,Grouped_Sources!$C:$C,1,FALSE)),"", INDIRECT(VLOOKUP($D19,Grouped_Sources!$C:$I,7,FALSE)))}
A20: 3 | B20: 18 | C20: =IF(G20 = "",F20,IF(OR(G20="alpha",G20="beta",G20="constant",G20="sd",G20="mean",G20="sample"),F20,F20&" "&G20)) -> PM_emission_inventories heavy_truck | D20: =F20&"_"&E20 -> PM_emission_inventories_南美洲 | E20: {=INDIRECT(ADDRESS(1,A20,1,1,"all_city_parameter_inputs"))} -> 南美洲 | F20: {=IF(AND(ISBLANK(INDIRECT(ADDRESS(B20,2,1,1,"all_city_parameter_inputs"))), ISBLANK(INDIRECT(ADDRESS(B20,1,1,1,"all_city_parameter_inputs")))), "", IF(ISBLANK(INDIRECT(ADDRESS(B20,1,1,1,"all_city_parameter_inputs"))), All_city_list!F19,INDIRECT(ADDRESS(B20,1,1,1,"all_city_parameter_inputs"))))} -> PM_emission_inventories | G20: {=IF(AND(ISBLANK(INDIRECT(ADDRESS(B20,3,1,1,"all_city_parameter_inputs"))),ISBLANK(INDIRECT(ADDRESS(B20,2,1,1,"all_city_parameter_inputs")))),"",IF(ISBLANK(INDIRECT(ADDRESS(B20,2,1,1,"all_city_parameter_inputs"))),"",INDIRECT(ADDRESS(B20,2,1,1,"all_city_parameter_inputs"))))} -> heavy_truck | H20: {=IF(ISBLANK(INDIRECT(ADDRESS(B20,A20,1,1,"all_city_parameter_inputs"))), "--",INDIRECT(ADDRESS(B20,A20,1,1,"all_city_parameter_inputs")))} -> 0.45445404 | I20: =IF(OR(G20="alpha",G20="beta",G20="sd",G20="mean"),"--",VLOOKUP(C20,Default!$B$5:$H$114,7,FALSE)) -> 0.45445404 | J20: =VLOOKUP(F20,Lookup!$C$5:$D$110,2, FALSE) -> Pollution values | K20: =VLOOKUP(C20,Default!$B$4:$E$114,4, FALSE) -> 0 | L20: {=IF(ISNA(VLOOKUP($D20,Grouped_Sources!$C:$C,1,FALSE)),"", INDIRECT(VLOOKUP($D20,Grouped_Sources!$C:$I,5,FALSE)))} | M20: {=IF(ISNA(VLOOKUP($D20,Grouped_Sources!$C:$C,1,FALSE)),"", INDIRECT(VLOOKUP($D20,Grouped_Sources!$C:$I,6,FALSE)))} | N20: {=IF(ISNA(VLOOKUP($D20,Grouped_Sources!$C:$C,1,FALSE)),"", INDIRECT(VLOOKUP($D20,Grouped_Sources!$C:$I,7,FALSE)))}
A21: 3 | B21: 19 | C21: =IF(G21 = "",F21,IF(OR(G21="alpha",G21="beta",G21="constant",G21="sd",G21="mean",G21="sample"),F21,F21&" "&G21)) -> PM_emission_inventories truck | D21: =F21&"_"&E21 -> PM_emission_inventories_南美洲 | E21: {=INDIRECT(ADDRESS(1,A21,1,1,"all_city_parameter_inputs"))} -> 南美洲 | F21: {=IF(AND(ISBLANK(INDIRECT(ADDRESS(B21,2,1,1,"all_city_parameter_inputs"))), ISBLANK(INDIRECT(ADDRESS(B21,1,1,1,"all_city_parameter_inputs")))), "", IF(ISBLANK(INDIRECT(ADDRESS(B21,1,1,1,"all_city_parameter_inputs"))), All_city_list!F20,INDIRECT(ADDRESS(B21,1,1,1,"all_city_parameter_inputs"))))} -> PM_emission_inventories | G21: {=IF(AND(ISBLANK(INDIRECT(ADDRESS(B21,3,1,1,"all_city_parameter_inputs"))),ISBLANK(INDIRECT(ADDRESS(B21,2,1,1,"all_city_parameter_inputs")))),"",IF(ISBLANK(INDIRECT(ADDRESS(B21,2,1,1,"all_city_parameter_inputs"))),"",INDIRECT(ADDRESS(B21,2,1,1,"all_city_parameter_inputs"))))} -> truck | H21: {=IF(ISBLANK(INDIRECT(ADDRESS(B21,A21,1,1,"all_city_parameter_inputs"))), "--",INDIRECT(ADDRESS(B21,A21,1,1,"all_city_parameter_inputs")))} -> 0.33879567 | I21: =IF(OR(G21="alpha",G21="beta",G21="sd",G21="mean"),"--",VLOOKUP(C21,Default!$B$5:$H$114,7,FALSE)) -> 0.33879567 | J21: =VLOOKUP(F21,Lookup!$C$5:$D$110,2, FALSE) -> Pollution values | K21: =VLOOKUP(C21,Default!$B$4:$E$114,4, FALSE) -> 0 | L21: {=IF(ISNA(VLOOKUP($D21,Grouped_Sources!$C:$C,1,FALSE)),"", INDIRECT(VLOOKUP($D21,Grouped_Sources!$C:$I,5,FALSE)))} | M21: {=IF(ISNA(VLOOKUP($D21,Grouped_Sources!$C:$C,1,FALSE)),"", INDIRECT(VLOOKUP($D21,Grouped_Sources!$C:$I,6,FALSE)))} | N21: {=IF(ISNA(VLOOKUP($D21,Grouped_Sources!$C:$C,1,FALSE)),"", INDIRECT(VLOOKUP($D21,Grouped_Sources!$C:$I,7,FALSE)))}
A22: 3 | B22: 20 | C22: =IF(G22 = "",F22,IF(OR(G22="alpha",G22="beta",G22="constant",G22="sd",G22="mean",G22="sample"),F22,F22&" "&G22)) -> PM_emission_inventories van | D22: =F22&"_"&E22 -> PM_emission_inventories_南美洲 | E22: {=INDIRECT(ADDRESS(1,A22,1,1,"all_city_parameter_inputs"))} -> 南美洲 | F22: {=IF(AND(ISBLANK(INDIRECT(ADDRESS(B22,2,1,1,"all_city_parameter_inputs"))), ISBLANK(INDIRECT(ADDRESS(B22,1,1,1,"all_city_parameter_inputs")))), "", IF(ISBLANK(INDIRECT(ADDRESS(B22,1,1,1,"all_city_parameter_inputs"))), All_city_list!F21,INDIRECT(ADDRESS(B22,1,1,1,"all_city_parameter_inputs"))))} -> PM_emission_inventories | G22: {=IF(AND(ISBLANK(INDIRECT(ADDRESS(B22,3,1,1,"all_city_parameter_inputs"))),ISBLANK(INDIRECT(ADDRESS(B22,2,1,1,"all_city_parameter_inputs")))),"",IF(ISBLANK(INDIRECT(ADDRESS(B22,2,1,1,"all_city_parameter_inputs"))),"",INDIRECT(ADDRESS(B22,2,1,1,"all_city_parameter_inputs"))))} -> van | H22: {=IF(ISBLANK(INDIRECT(ADDRESS(B22,A22,1,1,"all_city_parameter_inputs"))), "--",INDIRECT(ADDRESS(B22,A22,1,1,"all_city_parameter_inputs")))} -> 0 | I22: =IF(OR(G22="alpha",G22="beta",G22="sd",G22="mean"),"--",VLOOKUP(C22,Default!$B$5:$H$114,7,FALSE)) -> 0 | J22: =VLOOKUP(F22,Lookup!$C$5:$D$110,2, FALSE) -> Pollution values | K22: =VLOOKUP(C22,Default!$B$4:$E$114,4, FALSE) -> 0 | L22: {=IF(ISNA(VLOOKUP($D22,Grouped_Sources!$C:$C,1,FALSE)),"", INDIRECT(VLOOKUP($D22,Grouped_Sources!$C:$I,5,FALSE)))} | M22: {=IF(ISNA(VLOOKUP($D22,Grouped_Sources!$C:$C,1,FALSE)),"", INDIRECT(VLOOKUP($D22,Grouped_Sources!$C:$I,6,FALSE)))} | N22: {=IF(ISNA(VLOOKUP($D22,Grouped_Sources!$C:$C,1,FALSE)),"", INDIRECT(VLOOKUP($D22,Grouped_Sources!$C:$I,7,FALSE)))}
A23: 3 | B23: 21 | C23: =IF(G23 = "",F23,IF(OR(G23="alpha",G23="beta",G23="constant",G23="sd",G23="mean",G23="sample"),F23,F23&" "&G23)) -> PM_emission_inventories other | D23: =F23&"_"&E23 -> PM_emission_inventories_南美洲 | E23: {=INDIRECT(ADDRESS(1,A23,1,1,"all_city_parameter_inputs"))} -> 南美洲 | F23: {=IF(AND(ISBLANK(INDIRECT(ADDRESS(B23,2,1,1,"all_city_parameter_inputs"))), ISBLANK(INDIRECT(ADDRESS(B23,1,1,1,"all_city_parameter_inputs")))), "", IF(ISBLANK(INDIRECT(ADDRESS(B23,1,1,1,"all_city_parameter_inputs"))), All_city_list!F22,INDIRECT(ADDRESS(B23,1,1,1,"all_city_parameter_inputs"))))} -> PM_emission_inventories | G23: {=IF(AND(ISBLANK(INDIRECT(ADDRESS(B23,3,1,1,"all_city_parameter_inputs"))),ISBLANK(INDIRECT(ADDRESS(B23,2,1,1,"all_city_parameter_inputs")))),"",IF(ISBLANK(INDIRECT(ADDRESS(B23,2,1,1,"all_city_parameter_inputs"))),"",INDIRECT(ADDRESS(B23,2,1,1,"all_city_parameter_inputs"))))} -> other | H23: {=IF(ISBLANK(INDIRECT(ADDRESS(B23,A23,1,1,"all_city_parameter_inputs"))), "--",INDIRECT(ADDRESS(B23,A23,1,1,"all_city_parameter_inputs")))} -> 0 | I23: =IF(OR(G23="alpha",G23="beta",G23="sd",G23="mean"),"--",VLOOKUP(C23,Default!$B$5:$H$114,7,FALSE)) -> 0 | J23: =VLOOKUP(F23,Lookup!$C$5:$D$110,2, FALSE) -> Pollution values | K23: =VLOOKUP(C23,Default!$B$4:$E$114,4, FALSE) -> 0 | L23: {=IF(ISNA(VLOOKUP($D23,Grouped_Sources!$C:$C,1,FALSE)),"", INDIRECT(VLOOKUP($D23,Grouped_Sources!$C:$I,5,FALSE)))} | M23: {=IF(ISNA(VLOOKUP($D23,Grouped_Sources!$C:$C,1,FALSE)),"", INDIRECT(VLOOKUP($D23,Grouped_Sources!$C:$I,6,FALSE)))} | N23: {=IF(ISNA(VLOOKUP($D23,Grouped_Sources!$C:$C,1,FALSE)),"", INDIRECT(VLOOKUP($D23,Grouped_Sources!$C:$I,7,FALSE)))}
A24: 3 | B24: 22 | C24: =IF(G24 = "",F24,IF(OR(G24="alpha",G24="beta",G24="constant",G24="sd",G24="mean",G24="sample"),F24,F24&" "&G24)) -> PM_emission_inventories taxi | D24: =F24&"_"&E24 -> PM_emission_inventories_南美洲 | E24: {=INDIRECT(ADDRESS(1,A24,1,1,"all_city_parameter_inputs"))} -> 南美洲 | F24: {=IF(AND(ISBLANK(INDIRECT(ADDRESS(B24,2,1,1,"all_city_parameter_inputs"))), ISBLANK(INDIRECT(ADDRESS(B24,1,1,1,"all_city_parameter_inputs")))), "", IF(ISBLANK(INDIRECT(ADDRESS(B24,1,1,1,"all_city_parameter_inputs"))), All_city_list!F23,INDIRECT(ADDRESS(B24,1,1,1,"all_city_parameter_inputs"))))} -> PM_emission_inventories | G24: {=IF(AND(ISBLANK(INDIRECT(ADDRESS(B24,3,1,1,"all_city_parameter_inputs"))),ISBLANK(INDIRECT(ADDRESS(B24,2,1,1,"all_city_parameter_inputs")))),"",IF(ISBLANK(INDIRECT(ADDRESS(B24,2,1,1,"all_city_parameter_inputs"))),"",INDIRECT(ADDRESS(B24,2,1,1,"all_city_parameter_inputs"))))} -> taxi | H24: {=IF(ISBLANK(INDIRECT(ADDRESS(B24,A24,1,1,"all_city_parameter_inputs"))), "--",INDIRECT(ADDRESS(B24,A24,1,1,"all_city_parameter_inputs")))} -> 0 | I24: =IF(OR(G24="alpha",G24="beta",G24="sd",G24="mean"),"--",VLOOKUP(C24,Default!$B$5:$H$114,7,FALSE)) -> 0 | J24: =VLOOKUP(F24,Lookup!$C$5:$D$110,2, FALSE) -> Pollution values | K24: =VLOOKUP(C24,Default!$B$4:$E$114,4, FALSE) -> 0 | L24: {=IF(ISNA(VLOOKUP($D24,Grouped_Sources!$C:$C,1,FALSE)),"", INDIRECT(VLOOKUP($D24,Grouped_Sources!$C:$I,5,FALSE)))} | M24: {=IF(ISNA(VLOOKUP($D24,Grouped_Sources!$C:$C,1,FALSE)),"", INDIRECT(VLOOKUP($D24,Grouped_Sources!$C:$I,6,FALSE)))} | N24: {=IF(ISNA(VLOOKUP($D24,Grouped_Sources!$C:$C,1,FALSE)),"", INDIRECT(VLOOKUP($D24,Grouped_Sources!$C:$I,7,FALSE)))}
A25: 3 | B25: 23 | C25: =IF(G25 = "",F25,IF(OR(G25="alpha",G25="beta",G25="constant",G25="sd",G25="mean",G25="sample"),F25,F25&" "&G25)) -> PM_emission_inventories auto_rickshaw | D25: =F25&"_"&E25 -> PM_emission_inventories_南美洲 | E25: {=INDIRECT(ADDRESS(1,A25,1,1,"all_city_parameter_inputs"))} -> 南美洲 | F25: {=IF(AND(ISBLANK(INDIRECT(ADDRESS(B25,2,1,1,"all_city_parameter_inputs"))), ISBLANK(INDIRECT(ADDRESS(B25,1,1,1,"all_city_parameter_inputs")))), "", IF(ISBLANK(INDIRECT(ADDRESS(B25,1,1,1,"all_city_parameter_inputs"))), All_city_list!F24,INDIRECT(ADDRESS(B25,1,1,1,"all_city_parameter_inputs"))))} -> PM_emission_inventories | G25: {=IF(AND(ISBLANK(INDIRECT(ADDRESS(B25,3,1,1,"all_city_parameter_inputs"))),ISBLANK(INDIRECT(ADDRESS(B25,2,1,1,"all_city_parameter_inputs")))),"",IF(ISBLANK(INDIRECT(ADDRESS(B25,2,1,1,"all_city_parameter_inputs"))),"",INDIRECT(ADDRESS(B25,2,1,1,"all_city_parameter_inputs"))))} -> auto_rickshaw | H25: {=IF(ISBLANK(INDIRECT(ADDRESS(B25,A25,1,1,"all_city_parameter_inputs"))), "--",INDIRECT(ADDRESS(B25,A25,1,1,"all_city_parameter_inputs")))} -> 0 | I25: =IF(OR(G25="alpha",G25="beta",G25="sd",G25="mean"),"--",VLOOKUP(C25,Default!$B$5:$H$114,7,FALSE)) -> 0 | J25: =VLOOKUP(F25,Lookup!$C$5:$D$110,2, FALSE) -> Pollution values | K25: =VLOOKUP(C25,Default!$B$4:$E$114,4, FALSE) -> 0 | L25: https://www.who.int/publications/i/item/9789241565684 | M25: WHO report giving reported and estimated injury statistics at a country level. The underreporting for Colombia is approx 20% but we assumed that the underreporting at a city level is half this value, i.e. 10%. So parameter was set to 1-0.1= 0.9
A26: 3 | B26: 24 | C26: =IF(G26 = "",F26,IF(OR(G26="alpha",G26="beta",G26="constant",G26="sd",G26="mean",G26="sample"),F26,F26&" "&G26)) -> injury_reporting_rate | D26: =F26&"_"&E26 -> injury_reporting_rate_南美洲 | E26: {=INDIRECT(ADDRESS(1,A26,1,1,"all_city_parameter_inputs"))} -> 南美洲 | F26: {=IF(AND(ISBLANK(INDIRECT(ADDRESS(B26,2,1,1,"all_city_parameter_inputs"))), ISBLANK(INDIRECT(ADDRESS(B26,1,1,1,"all_city_parameter_inputs")))), "", IF(ISBLANK(INDIRECT(ADDRESS(B26,1,1,1,"all_city_parameter_inputs"))), All_city_list!F25,INDIRECT(ADDRESS(B26,1,1,1,"all_city_parameter_inputs"))))} -> injury_reporting_rate | G26: {=IF(AND(ISBLANK(INDIRECT(ADDRESS(B26,3,1,1,"all_city_parameter_inputs"))),ISBLANK(INDIRECT(ADDRESS(B26,2,1,1,"all_city_parameter_inputs")))),"",IF(ISBLANK(INDIRECT(ADDRESS(B26,2,1,1,"all_city_parameter_inputs"))),"",INDIRECT(ADDRESS(B26,2,1,1,"all_city_parameter_inputs"))))} -> constant | H26: {=IF(ISBLANK(INDIRECT(ADDRESS(B26,A26,1,1,"all_city_parameter_inputs"))), "--",INDIRECT(ADDRESS(B26,A26,1,1,"all_city_parameter_inputs")))} -> 0.8982419 | I26: =IF(OR(G26="alpha",G26="beta",G26="sd",G26="mean"),"--",VLOOKUP(C26,Default!$B$5:$H$114,7,FALSE)) -> 1 | J26: =VLOOKUP(F26,Lookup!$C$5:$D$110,2, FALSE) -> Injury values | K26: =VLOOKUP(C26,Default!$B$4:$E$114,4, FALSE) -> rate at which injuries are reported | L26: {=IF(ISNA(VLOOKUP($D26,Grouped_Sources!$C:$C,1,FALSE)),"", INDIRECT(VLOOKUP($D26,Grouped_Sources!$C:$I,5,FALSE)))} | M26: {=IF(ISNA(VLOOKUP($D26,Grouped_Sources!$C:$C,1,FALSE)),"", INDIRECT(VLOOKUP($D26,Grouped_Sources!$C:$I,6,FALSE)))} | N26: {=IF(ISNA(VLOOKUP($D26,Grouped_Sources!$C:$C,1,FALSE)),"", INDIRECT(VLOOKUP($D26,Grouped_Sources!$C:$I,7,FALSE)))}
A27: 3 | B27: 25 | C27: =IF(G27 = "",F27,IF(OR(G27="alpha",G27="beta",G27="constant",G27="sd",G27="mean",G27="sample"),F27,F27&" "&G27)) -> injury_reporting_rate | D27: =F27&"_"&E27 -> injury_reporting_rate_南美洲 | E27: {=INDIRECT(ADDRESS(1,A27,1,1,"all_city_parameter_inputs"))} -> 南美洲 | F27: {=IF(AND(ISBLANK(INDIRECT(ADDRESS(B27,2,1,1,"all_city_parameter_inputs"))), ISBLANK(INDIRECT(ADDRESS(B27,1,1,1,"all_city_parameter_inputs")))), "", IF(ISBLANK(INDIRECT(ADDRESS(B27,1,1,1,"all_city_parameter_inputs"))), All_city_list!F26,INDIRECT(ADDRESS(B27,1,1,1,"all_city_parameter_inputs"))))} -> injury_reporting_rate | G27: {=IF(AND(ISBLANK(INDIRECT(ADDRESS(B27,3,1,1,"all_city_parameter_inputs"))),ISBLANK(INDIRECT(ADDRESS(B27,2,1,1,"all_city_parameter_inputs")))),"",IF(ISBLANK(INDIRECT(ADDRESS(B27,2,1,1,"all_city_parameter_inputs"))),"",INDIRECT(ADDRESS(B27,2,1,1,"all_city_parameter_inputs"))))} -> alpha | H27: {=IF(ISBLANK(INDIRECT(ADDRESS(B27,A27,1,1,"all_city_parameter_inputs"))), "--",INDIRECT(ADDRESS(B27,A27,1,1,"all_city_parameter_inputs")))} -> -- | I27: =IF(OR(G27="alpha",G27="beta",G27="sd",G27="mean"),"--",VLOOKUP(C27,Default!$B$5:$H$114,7,FALSE)) -> -- | J27: =VLOOKUP(F27,Lookup!$C$5:$D$110,2, FALSE) -> Injury values | K27: =VLOOKUP(C27,Default!$B$4:$E$114,4, FALSE) -> rate at which injuries are reported | L27: {=IF(ISNA(VLOOKUP($D27,Grouped_Sources!$C:$C,1,FALSE)),"", INDIRECT(VLOOKUP($D27,Grouped_Sources!$C:$I,5,FALSE)))} | M27: {=IF(ISNA(VLOOKUP($D27,Grouped_Sources!$C:$C,1,FALSE)),"", INDIRECT(VLOOKUP($D27,Grouped_Sources!$C:$I,6,FALSE)))} | N27: {=IF(ISNA(VLOOKUP($D27,Grouped_Sources!$C:$C,1,FALSE)),"", INDIRECT(VLOOKUP($D27,Grouped_Sources!$C:$I,7,FALSE)))}
A28: 3 | B28: 26 | C28: =IF(G28 = "",F28,IF(OR(G28="alpha",G28="beta",G28="constant",G28="sd",G28="mean",G28="sample"),F28,F28&" "&G28)) -> injury_reporting_rate | D28: =F28&"_"&E28 -> injury_reporting_rate_南美洲 | E28: {=INDIRECT(ADDRESS(1,A28,1,1,"all_city_parameter_inputs"))} -> 南美洲 | F28: {=IF(AND(ISBLANK(INDIRECT(ADDRESS(B28,2,1,1,"all_city_parameter_inputs"))), ISBLANK(INDIRECT(ADDRESS(B28,1,1,1,"all_city_parameter_inputs")))), "", IF(ISBLANK(INDIRECT(ADDRESS(B28,1,1,1,"all_city_parameter_inputs"))), All_city_list!F27,INDIRECT(ADDRESS(B28,1,1,1,"all_city_parameter_inputs"))))} -> injury_reporting_rate | G28: {=IF(AND(ISBLANK(INDIRECT(ADDRESS(B28,3,1,1,"all_city_parameter_inputs"))),ISBLANK(INDIRECT(ADDRESS(B28,2,1,1,"all_city_parameter_inputs")))),"",IF(ISBLANK(INDIRECT(ADDRESS(B28,2,1,1,"all_city_parameter_inputs"))),"",INDIRECT(ADDRESS(B28,2,1,1,"all_city_parameter_inputs"))))} -> beta | H28: {=IF(ISBLANK(INDIRECT(ADDRESS(B28,A28,1,1,"all_city_parameter_inputs"))), "--",INDIRECT(ADDRESS(B28,A28,1,1,"all_city_parameter_inputs")))} -> -- | I28: =IF(OR(G28="alpha",G28="beta",G28="sd",G28="mean"),"--",VLOOKUP(C28,Default!$B$5:$H$114,7,FALSE)) -> -- | J28: =VLOOKUP(F28,Lookup!$C$5:$D$110,2, FALSE) -> Injury values | K28: =VLOOKUP(C28,Default!$B$4:$E$114,4, FALSE) -> rate at which injuries are reported | L28: assumes no bias in the disease data, distribution values need updating
A29: 3 | B29: 27 | C29: =IF(G29 = "",F29,IF(OR(G29="alpha",G29="beta",G29="constant",G29="sd",G29="mean",G29="sample"),F29,F29&" "&G29)) -> chronic_disease_scalar | D29: =F29&"_"&E29 -> chronic_disease_scalar_南美洲 | E29: {=INDIRECT(ADDRESS(1,A29,1,1,"all_city_parameter_inputs"))} -> 南美洲 | F29: {=IF(AND(ISBLANK(INDIRECT(ADDRESS(B29,2,1,1,"all_city_parameter_inputs"))), ISBLANK(INDIRECT(ADDRESS(B29,1,1,1,"all_city_parameter_inputs")))), "", IF(ISBLANK(INDIRECT(ADDRESS(B29,1,1,1,"all_city_parameter_inputs"))), All_city_list!F28,INDIRECT(ADDRESS(B29,1,1,1,"all_city_parameter_inputs"))))} -> chronic_disease_scalar | G29: {=IF(AND(ISBLANK(INDIRECT(ADDRESS(B29,3,1,1,"all_city_parameter_inputs"))),ISBLANK(INDIRECT(ADDRESS(B29,2,1,1,"all_city_parameter_inputs")))),"",IF(ISBLANK(INDIRECT(ADDRESS(B29,2,1,1,"all_city_parameter_inputs"))),"",INDIRECT(ADDRESS(B29,2,1,1,"all_city_parameter_inputs"))))} -> constant | H29: {=IF(ISBLANK(INDIRECT(ADDRESS(B29,A29,1,1,"all_city_parameter_inputs"))), "--",INDIRECT(ADDRESS(B29,A29,1,1,"all_city_parameter_inputs")))} -> 1 | I29: =IF(OR(G29="alpha",G29="beta",G29="sd",G29="mean"),"--",VLOOKUP(C29,Default!$B$5:$H$114,7,FALSE)) -> 1 | J29: =VLOOKUP(F29,Lookup!$C$5:$D$110,2, FALSE) -> Health values | K29: =VLOOKUP(C29,Default!$B$4:$E$114,4, FALSE) -> scalar for GBD data | L29: {=IF(ISNA(VLOOKUP($D29,Grouped_Sources!$C:$C,1,FALSE)),"", INDIRECT(VLOOKUP($D29,Grouped_Sources!$C:$I,5,FALSE)))} | M29: {=IF(ISNA(VLOOKUP($D29,Grouped_Sources!$C:$C,1,FALSE)),"", INDIRECT(VLOOKUP($D29,Grouped_Sources!$C:$I,6,FALSE)))} | N29: {=IF(ISNA(VLOOKUP($D29,Grouped_Sources!$C:$C,1,FALSE)),"", INDIRECT(VLOOKUP($D29,Grouped_Sources!$C:$I,7,FALSE)))}
A30: 3 | B30: 28 | C30: =IF(G30 = "",F30,IF(OR(G30="alpha",G30="beta",G30="constant",G30="sd",G30="mean",G30="sample"),F30,F30&" "&G30)) -> chronic_disease_scalar | D30: =F30&"_"&E30 -> chronic_disease_scalar_南美洲 | E30: {=INDIRECT(ADDRESS(1,A30,1,1,"all_city_parameter_inputs"))} -> 南美洲 | F30: {=IF(AND(ISBLANK(INDIRECT(ADDRESS(B30,2,1,1,"all_city_parameter_inputs"))), ISBLANK(INDIRECT(ADDRESS(B30,1,1,1,"all_city_parameter_inputs")))), "", IF(ISBLANK(INDIRECT(ADDRESS(B30,1,1,1,"all_city_parameter_inputs"))), All_city_list!F29,INDIRECT(ADDRESS(B30,1,1,1,"all_city_parameter_inputs"))))} -> chronic_disease_scalar | G30: {=IF(AND(ISBLANK(INDIRECT(ADDRESS(B30,3,1,1,"all_city_parameter_inputs"))),ISBLANK(INDIRECT(ADDRESS(B30,2,1,1,"all_city_parameter_inputs")))),"",IF(ISBLANK(INDIRECT(ADDRESS(B30,2,1,1,"all_city_parameter_inputs"))),"",INDIRECT(ADDRESS(B30,2,1,1,"all_city_parameter_inputs"))))} -> mean | H30: {=IF(ISBLANK(INDIRECT(ADDRESS(B30,A30,1,1,"all_city_parameter_inputs"))), "--",INDIRECT(ADDRESS(B30,A30,1,1,"all_city_parameter_inputs")))} -> -- | I30: =IF(OR(G30="alpha",G30="beta",G30="sd",G30="mean"),"--",VLOOKUP(C30,Default!$B$5:$H$114,7,FALSE)) -> -- | J30: =VLOOKUP(F30,Lookup!$C$5:$D$110,2, FALSE) -> Health values | K30: =VLOOKUP(C30,Default!$B$4:$E$114,4, FALSE) -> scalar for GBD data | L30: {=IF(ISNA(VLOOKUP($D30,Grouped_Sources!$C:$C,1,FALSE)),"", INDIRECT(VLOOKUP($D30,Grouped_Sources!$C:$I,5,FALSE)))} | M30: {=IF(ISNA(VLOOKUP($D30,Grouped_Sources!$C:$C,1,FALSE)),"", INDIRECT(VLOOKUP($D30,Grouped_Sources!$C:$I,6,FALSE)))} | N30: {=IF(ISNA(VLOOKUP($D30,Grouped_Sources!$C:$C,1,FALSE)),"", INDIRECT(VLOOKUP($D30,Grouped_Sources!$C:$I,7,FALSE)))}
A31: 3 | B31: 29 | C31: =IF(G31 = "",F31,IF(OR(G31="alpha",G31="beta",G31="constant",G31="sd",G31="mean",G31="sample"),F31,F31&" "&G31)) -> chronic_disease_scalar | D31: =F31&"_"&E31 -> chronic_disease_scalar_南美洲 | E31: {=INDIRECT(ADDRESS(1,A31,1,1,"all_city_parameter_inputs"))} -> 南美洲 | F31: {=IF(AND(ISBLANK(INDIRECT(ADDRESS(B31,2,1,1,"all_city_parameter_inputs"))), ISBLANK(INDIRECT(ADDRESS(B31,1,1,1,"all_city_parameter_inputs")))), "", IF(ISBLANK(INDIRECT(ADDRESS(B31,1,1,1,"all_city_parameter_inputs"))), All_city_list!F30,INDIRECT(ADDRESS(B31,1,1,1,"all_city_parameter_inputs"))))} -> chronic_disease_scalar | G31: {=IF(AND(ISBLANK(INDIRECT(ADDRESS(B31,3,1,1,"all_city_parameter_inputs"))),ISBLANK(INDIRECT(ADDRESS(B31,2,1,1,"all_city_parameter_inputs")))),"",IF(ISBLANK(INDIRECT(ADDRESS(B31,2,1,1,"all_city_parameter_inputs"))),"",INDIRECT(ADDRESS(B31,2,1,1,"all_city_parameter_inputs"))))} -> sd | H31: {=IF(ISBLANK(INDIRECT(ADDRESS(B31,A31,1,1,"all_city_parameter_inputs"))), "--",INDIRECT(ADDRESS(B31,A31,1,1,"all_city_parameter_inputs")))} -> -- | I31: =IF(OR(G31="alpha",G31="beta",G31="sd",G31="mean"),"--",VLOOKUP(C31,Default!$B$5:$H$114,7,FALSE)) -> -- | J31: =VLOOKUP(F31,Lookup!$C$5:$D$110,2, FALSE) -> Health values | K31: =VLOOKUP(C31,Default!$B$4:$E$114,4, FALSE) -> scalar for GBD data | L31: https://www.who.int/publications/m/item/who-air-quality-database-2022 | M31: WHO Air Quality Database, Update 2022
A32: 3 | B32: 30 | C32: =IF(G32 = "",F32,IF(OR(G32="alpha",G32="beta",G32="constant",G32="sd",G32="mean",G32="sample"),F32,F32&" "&G32)) -> pm_conc_base (from Edgar) | D32: =F32&"_"&E32 -> pm_conc_base (from Edgar)_南美洲 | E32: {=INDIRECT(ADDRESS(1,A32,1,1,"all_city_parameter_inputs"))} -> 南美洲 | F32: {=IF(AND(ISBLANK(INDIRECT(ADDRESS(B32,2,1,1,"all_city_parameter_inputs"))), ISBLANK(INDIRECT(ADDRESS(B32,1,1,1,"all_city_parameter_inputs")))), "", IF(ISBLANK(INDIRECT(ADDRESS(B32,1,1,1,"all_city_parameter_inputs"))), All_city_list!F31,INDIRECT(ADDRESS(B32,1,1,1,"all_city_parameter_inputs"))))} -> pm_conc_base (from Edgar) | G32: {=IF(AND(ISBLANK(INDIRECT(ADDRESS(B32,3,1,1,"all_city_parameter_inputs"))),ISBLANK(INDIRECT(ADDRESS(B32,2,1,1,"all_city_parameter_inputs")))),"",IF(ISBLANK(INDIRECT(ADDRESS(B32,2,1,1,"all_city_parameter_inputs"))),"",INDIRECT(ADDRESS(B32,2,1,1,"all_city_parameter_inputs"))))} -> constant | H32: {=IF(ISBLANK(INDIRECT(ADDRESS(B32,A32,1,1,"all_city_parameter_inputs"))), "--",INDIRECT(ADDRESS(B32,A32,1,1,"all_city_parameter_inputs")))} -> 12.69 | I32: =IF(OR(G32="alpha",G32="beta",G32="sd",G32="mean"),"--",VLOOKUP(C32,Default!$B$5:$H$114,7,FALSE)) -> #N/A | J32: =VLOOKUP(F32,Lookup!$C$5:$D$110,2, FALSE) -> #N/A | K32: =VLOOKUP(C32,Default!$B$4:$E$114,4, FALSE) -> #N/A | L32: {=IF(ISNA(VLOOKUP($D32,Grouped_Sources!$C:$C,1,FALSE)),"", INDIRECT(VLOOKUP($D32,Grouped_Sources!$C:$I,5,FALSE)))} | M32: {=IF(ISNA(VLOOKUP($D32,Grouped_Sources!$C:$C,1,FALSE)),"", INDIRECT(VLOOKUP($D32,Grouped_Sources!$C:$I,6,FALSE)))} | N32: {=IF(ISNA(VLOOKUP($D32,Grouped_Sources!$C:$C,1,FALSE)),"", INDIRECT(VLOOKUP($D32,Grouped_Sources!$C:$I,7,FALSE)))}
A33: 3 | B33: 31 | C33: =IF(G33 = "",F33,IF(OR(G33="alpha",G33="beta",G33="constant",G33="sd",G33="mean",G33="sample"),F33,F33&" "&G33)) -> pm_conc_base (from Edgar) | D33: =F33&"_"&E33 -> pm_conc_base (from Edgar)_南美洲 | E33: {=INDIRECT(ADDRESS(1,A33,1,1,"all_city_parameter_inputs"))} -> 南美洲 | F33: {=IF(AND(ISBLANK(INDIRECT(ADDRESS(B33,2,1,1,"all_city_parameter_inputs"))), ISBLANK(INDIRECT(ADDRESS(B33,1,1,1,"all_city_parameter_inputs")))), "", IF(ISBLANK(INDIRECT(ADDRESS(B33,1,1,1,"all_city_parameter_inputs"))), All_city_list!F32,INDIRECT(ADDRESS(B33,1,1,1,"all_city_parameter_inputs"))))} -> pm_conc_base (from Edgar) | G33: {=IF(AND(ISBLANK(INDIRECT(ADDRESS(B33,3,1,1,"all_city_parameter_inputs"))),ISBLANK(INDIRECT(ADDRESS(B33,2,1,1,"all_city_parameter_inputs")))),"",IF(ISBLANK(INDIRECT(ADDRESS(B33,2,1,1,"all_city_parameter_inputs"))),"",INDIRECT(ADDRESS(B33,2,1,1,"all_city_parameter_inputs"))))} -> mean | H33: {=IF(ISBLANK(INDIRECT(ADDRESS(B33,A33,1,1,"all_city_parameter_inputs"))), "--",INDIRECT(ADDRESS(B33,A33,1,1,"all_city_parameter_inputs")))} -> -- | I33: =IF(OR(G33="alpha",G33="beta",G33="sd",G33="mean"),"--",VLOOKUP(C33,Default!$B$5:$H$114,7,FALSE)) -> -- | J33: =VLOOKUP(F33,Lookup!$C$5:$D$110,2, FALSE) -> #N/A | K33: =VLOOKUP(C33,Default!$B$4:$E$114,4, FALSE) -> #N/A | L33: {=IF(ISNA(VLOOKUP($D33,Grouped_Sources!$C:$C,1,FALSE)),"", INDIRECT(VLOOKUP($D33,Grouped_Sources!$C:$I,5,FALSE)))} | M33: {=IF(ISNA(VLOOKUP($D33,Grouped_Sources!$C:$C,1,FALSE)),"", INDIRECT(VLOOKUP($D33,Grouped_Sources!$C:$I,6,FALSE)))} | N33: {=IF(ISNA(VLOOKUP($D33,Grouped_Sources!$C:$C,1,FALSE)),"", INDIRECT(VLOOKUP($D33,Grouped_Sources!$C:$I,7,FALSE)))}
