Workbook

Sheet Readme
B3: Spreadsheet giving details about the various input parameters used in the Value of Information script of ITHIM Global
B5: blue cells | C5: contain formula
B6: green cells | C6: need manual filling in
B10: Tab name | C10: Description
B11: all_city_parameter_inputs | C11: Table detailing all the city specific parameters based on the csv file with the same name and used as input into R
B12: All_city_list | C12: List of all city specific parameters including their source and and explanation of what the parameter does. Takes its values from all_city_parameter_inputs and Default tab. Parameter explanations and sources are added manually. To add a new city, add the city to the all_city_parameter_inputs tab and copy down the blue cells of the last populated row. If the structure of all_city_parameter_inputs is changed, add or delete rows for all cities to ensure the parameter descriptions and references are still in line with the correct parameter. The input values from all_city_parameter_inputs are currently being read based on their row and column value.
B13: all_global_parameter_inputs | C13: Details the global parameters, used as input file for ITHIM runs.
B14: All_global_list | C14: Details the values of the global parameters, i.e. the values that are not city specific. Reads values from all_global_parameter_inputs tab and Default tab and gives further information of where these values come from.
B15: Default | C15: List default values for all parameters, parameter explanations added to this tab are used in All_city_list
B16: Further_input_files | C16: Details where the additional input files needed for an ITHIM run can be found within the ITHIM-Global R package
B17: Grouped_sources | C17: Lookup table that shows from which city input parameter information on the all_city_list tab can be copied for other cities
B18: City_xxx | C18: Pivot tables comparing parameter values for different cities for different parameter classifications Pivot tables are set up to allow the inclusion of text values if needed (https://www.howtoexcel.org/pivot-tables/summarizing-text/)
B19: Lookup | C19: table linking different parameter names and classifications
B24: Document history
B25: version | C25: Changes made | D25: Author | E25: Date
B26: v1.0 | C26: Initial set-up | D26: AKS | E26: 44481
B27: v1.1 | C27: Added further info for default parameters | D27: AKS | E27: 44503
B28: v2.0 | C28: Added parameters for Latam Cities PM_emission_inventories values updated for Sao Paulo, Belo Horizonte, Bogota, Santiago, Mexico City, Buenos Aires pm_conc_base updated for Sao Paulo, Bangalore, Vizaq, Santiago, Mexico City pm_trans_share updated for Sao Paulo, Belo Horizonte, Bogota, Santiago | D28: AKS | E28: 44572
B29: v3.0 | C29: Added CO2_emission_confidence to all_city_parameter_inputs tab, also added all_global_parameter_inputs tab used as input when running ITHIM and updated All_global_list from the original Global tab accordingly | D29: AKS | E29: 44608
B30: v3.1 | C30: Added some more description of parameters, added Further_input_files sheet | D30: AKS | E30: 44615
B31: v3.2 | C31: Added additional parameter explanations, added Grouped_Sources tab which fills in the location of the input parameters based on information from other cities | D31: AKS | E31: 44627
B32: v4.0 | C32: Updated truck_to_car_ratio and injury_reporting_rate parameters and also added new car_occupancy_ratio parameter | D32: AKS | E32: 44706
B33: v4.1 | C33: Added further info for car_occupancy_ratio and where default values are defined in ITHIM-R, set add_bus_drivers and add_car_drivers to T, added car driver speed to default values | D33: AKS | E33: 44711
B34: v5.0 | C34: Updated bus_passenger_ratios, added documentation for rail_walk_time and bus_walk_time | D34: AKS | E34: 44728
B35: v6.0 | C35: Changed the values for the parameter: "PM_emission_inventories" to values from EDGAR v6.1 which corresponds to 2018 data. Note that this change is only applicable for the 20 Latin American cities and has not been done for the other cities (yet). Delhi, Bangalore, Vizag, and Cape Town have not been updated. Values from Antofagasta were used for Iquique and Alto Hospicio, and values from Valdivia were used for Temuco due to lack of EDGAR data. | D35: HK | E35: 44734
B36: v7.0 | C36: Double checked and changed some values for the parameters: "pm_conc_base" and "pm_trans_share" including matching the constant to the mean values in rows 19 and 20. Note that this change is only applicable for the 20 Latin American cities and has not been done for the other cities (yet). Delhi, Bangalore, Vizag, and Cape Town have not been updated. These values come from: “…Dropbox\ITHIM Global\Methods and Processes\Air Pollution\Emissions and air pollution calculations - Rahul & Haneen\Databases used\database_source_apport_studies_v2_0_26_9_2015.xls" | D36: HK | E36: 44739
B37: v7.1 | C37: Updated sources for PM_emission_inventories, pm_conc_base and pm_trans_share in All_city_list using info supplied by Haneen | D37: AKS | E37: 44741
... B71: v35.0 | C71: Added additional MET parameters and changed walking and cycling MMETs to METs | D71: AKS | E71: 45164

Sheet all_city_parameter_inputs
A1: parameter | B1: detail | C1: accra | D1: sao_paulo | E1: delhi | F1: bangalore | G1: vizag | H1: belo_horizonte | I1: bogota | J1: santiago | K1: mexico_city | L1: buenos_aires | M1: cape_town | N1: medellin | O1: cali | P1: montevideo | Q1: antofagasta | R1: arica | S1: copiapo | T1: coquimbo_laserena | U1: iquique_altohospicio | V1: osorno | W1: puerto_montt | X1: san_antonio | Y1: temuco_padrelascasas | Z1: valdivia | AA1: gran_valparaiso | AB1: nairobi | AC1: kisumu | AD1: port_louis
A2: speeds | B2: auto_rickshaw | C2: 4 | E2: 4 | F2: 4 | G2: 4 | M2: 4 | AB2: 4 | AC2: 4 | AD2: 4
B3: bus | C3: 12 | D3: 8.1 | E3: 12 | F3: 12 | G3: 12 | H3: 8.1 | I3: 8.1 | J3: 8.1 | K3: 8.1 | L3: 8.1 | M3: 12 | N3: 8.1 | O3: 8.1 | P3: 8.1 | Q3: 13 | R3: 13 | S3: 13 | T3: 13 | U3: 13 | V3: 13 | W3: 13 | X3: 7.1 | Y3: 13 | Z3: 13 | AA3: 7.1 | AB3: 12 | AC3: 12 | AD3: 12
B4: car | C4: 15 | D4: 13.8 | E4: 15 | F4: 15 | G4: 15 | H4: 13.8 | I4: 13.8 | J4: 13.8 | K4: 13.8 | L4: 13.8 | M4: 15 | N4: 13.8 | O4: 13.8 | P4: 13.8 | Q4: 16 | R4: 16 | S4: 16 | T4: 16 | U4: 16 | V4: 16 | W4: 16 | X4: 12.8 | Y4: 16 | Z4: 16 | AA4: 12.8 | AB4: 15 | AC4: 15 | AD4: 15
B5: cycle | C5: 6 | D5: 7.2 | E5: 6 | F5: 6 | G5: 6 | H5: 7.2 | I5: 7.2 | J5: 8.4 | K5: 7.2 | L5: 8.4 | M5: 6 | N5: 8.4 | O5: 8.4 | P5: 8.4 | Q5: 7.2 | R5: 7.2 | S5: 7.2 | T5: 8.9 | U5: 7.2 | V5: 8.9 | W5: 8.9 | X5: 7.9 | Y5: 8.9 | Z5: 8.9 | AA5: 7.9 | AB5: 6 | AC5: 6 | AD5: 6
B6: subway | D6: 18.1 | H6: 18.1 | I6: 18.1 | J6: 18.1 | K6: 18.1 | L6: 18.1 | N6: 18.1 | O6: 18.1 | P6: 18.1
B7: motorcycle | C7: 15 | D7: 15.2 | E7: 15 | F7: 15 | G7: 15 | H7: 15.2 | I7: 15.2 | J7: 18.4 | K7: 15.2 | L7: 18.4 | M7: 15 | N7: 18.4 | O7: 18.4 | P7: 18.4 | Q7: 16 | R7: 16 | S7: 16 | T7: 16 | U7: 16 | V7: 16 | W7: 16 | X7: 17.4 | Y7: 16 | Z7: 16 | AA7: 17.4 | AB7: 15 | AC7: 15 | AD7: 15
B8: other | D8: 9.1 | H8: 9.1 | I8: 9.1 | J8: 9.1 | K8: 9.1 | L8: 9.1 | N8: 9.1 | O8: 9.1 | P8: 9.1 | X8: 8.1 | AA8: 8.1
B9: pedestrian | C9: 2 | D9: 2.5 | E9: 2 | F9: 2 | G9: 2 | H9: 2.5 | I9: 2.5 | J9: 3 | K9: 2.5 | L9: 3 | M9: 2 | N9: 3 | O9: 3 | P9: 3 | Q9: 2.5 | R9: 2.5 | S9: 2.5 | T9: 3.5 | U9: 2.5 | V9: 3.5 | W9: 3.5 | X9: 2.5 | Y9: 3.5 | Z9: 3.5 | AA9: 2.5 | AB9: 2 | AC9: 2 | AD9: 2
B10: rail | C10: 20.6 | D10: 21.9 | E10: 20.6 | F10: 20.6 | G10: 20.6 | H10: 21.9 | I10: 21.9 | J10: 23.2 | K10: 21.9 | L10: 23.2 | M10: 20.6 | N10: 23.2 | O10: 23.2 | P10: 23.2 | Q10: 23.2 | R10: 23.2 | S10: 23.2 | T10: 23.2 | U10: 23.2 | V10: 23.2 | W10: 23.2 | X10: 23.2 | Y10: 23.2 | Z10: 23.2 | AA10: 23.2 | AB10: 20.6 | AC10: 20.6 | AD10: 20.6
B11: taxi | C11: 12 | D11: 12.56 | E11: 12 | F11: 12 | G11: 12 | H11: 12.56 | I11: 12.56 | J11: 13.1 | K11: 12.56 | L11: 13.1 | M11: 12 | N11: 13.1 | O11: 13.1 | P11: 13.1 | Q11: 14.1 | R11: 14.1 | S11: 14.1 | T11: 14.1 | U11: 14.1 | V11: 14.1 | W11: 14.1 | X11: 12.1 | Y11: 14.1 | Z11: 14.1 | AA11: 12.1 | AB11: 12 | AC11: 12 | AD11: 12
B12: truck | C12: 12 | D12: 8.1 | E12: 12 | F12: 12 | G12: 12 | H12: 8.1 | I12: 8.1 | J12: 8.1 | K12: 8.1 | L12: 8.1 | M12: 12 | N12: 8.1 | O12: 8.1 | P12: 8.1 | Q12: 13 | R12: 13 | S12: 13 | T12: 13 | U12: 13 | V12: 13 | W12: 13 | X12: 7.1 | Y12: 13 | Z12: 13 | AA12: 7.1 | AB12: 12 | AC12: 12 | AD12: 12
B13: van | C13: 15 | D13: 13.8 | E13: 15 | F13: 15 | G13: 15 | H13: 13.8 | I13: 13.8 | J13: 13.8 | K13: 13.8 | L13: 13.8 | M13: 15 | N13: 13.8 | O13: 13.8 | P13: 13.8 | Q13: 16 | R13: 16 | S13: 16 | T13: 16 | U13: 16 | V13: 16 | W13: 16 | X13: 12.8 | Y13: 16 | Z13: 16 | AA13: 12.8 | AB13: 15 | AC13: 15 | AD13: 15
A14: PM_emission_inventories | B14: motorcycle | C14: 0.002436234 | D14: 0.039413582 | E14: 0.16982169 | F14: 0.15864142 | G14: 0.11166396 | H14: 0.042782254 | I14: 0.0023031654 | J14: 0.0045315414 | K14: 0.013907217 | L14: 0.0032161983 | M14: 0.00749 | N14: 0.0016582895 | O14: 0.0022620858 | P14: 0.0028496403 | Q14: 0.0044194488 | R14: 0.0053226305 | S14: 0.0037372275 | T14: 0.006158745 | U14: 0.0044194488 | V14: 0.0028141163 | W14: 0.0051396824 | X14: 0.0036966513 | Y14: 0.002292726 | Z14: 0.002292726 | AA14: 0.0037719603 | AB14: 0.002317103 | AC14: 0.001402933 | AD14: 0.001675769
B15: car | C15: 0.5899859 | D15: 0.60887295 | E15: 0.395799 | F15: 0.3697417 | G15: 0.2602528 | H15: 0.66091308 | I15: 0.081980353 | J15: 0.52744651 | K15: 0.37072863 | L15: 0.18876937 | M15: 0.205 | N15: 0.059026312 | O15: 0.080518122 | P15: 0.10124173 | Q15: 0.5143994 | R15: 0.61952493 | S15: 0.43499279 | T15: 0.7168441 | U15: 0.5143994 | V15: 0.3275472 | W15: 0.59823132 | X15: 0.4302698 | Y15: 0.26686052 | Z15: 0.26686052 | AA15: 0.43890721 | AB15: 0.6899423 | AC15: 0.4177371 | AD15: 0.4269001
B16: bus_driver | C16: 0.04993458 | D16: 0.042887964 | E16: 0.18943069 | F16: 0.17631324 | G16: 0.18498184 | H16: 0.037426145 | I16: 0.12246677 | J16: 0.065633874 | K16: 0.0098461421 | L16: 0.094953763 | M16: 0.216 | N16: 0.1324222 | O16: 0.11069152 | P16: 0.11416744 | Q16: 0.064957627 | R16: 0.054413638 | S16: 0.072890653 | T16: 0.039380608 | U16: 0.064957627 | V16: 0.094991495 | W16: 0.059844227 | X16: 0.073106708 | Y16: 0.12672063 | Z16: 0.12672063 | AA16: 0.077462117 | AB16: 0.04216746 | AC16: 0.06723986 | AD16: 0.07158555
B17: big_truck | C17: 0.1924163 | D17: 0.1506294 | E17: 0.2285369 | F17: 0.2800284 | G17: 0.4270751 | H17: 0.12082875 | I17: 0.45445404 | J17: 0.20465102 | K17: 0.41246744 | L17: 0.44637056 | M17: 0.396 | N17: 0.44055714 | O17: 0.50030804 | P17: 0.46368543 | Q17: 0.2205242 | R17: 0.15680528 | S17: 0.26877929 | T17: 0.11897294 | U17: 0.2205242 | V17: 0.28846334 | W17: 0.15649014 | X17: 0.2726754 | Y17: 0.22235078 | Z17: 0.22235078 | AA17: 0.24654564 | AB17: 0.1254658 | AC17: 0.2902066 | AD17: 0.2627118
B18: truck | C18: 0.16522704 | D18: 0.15819611 | E18: 0.0164117 | F18: 0.01527525 | G18: 0.01602626 | H18: 0.13804977 | I18: 0.33879567 | J18: 0.19773705 | K18: 0.19305057 | L18: 0.26669011 | M18: 0.176 | N18: 0.36633606 | O18: 0.30622024 | P18: 0.31805576 | Q18: 0.19569932 | R18: 0.16393352 | S18: 0.21960004 | T18: 0.11864361 | U18: 0.19569932 | V18: 0.28618384 | W18: 0.18029463 | X18: 0.22025144 | Y18: 0.38177534 | Z18: 0.38177534 | AA18: 0.23331307 | AB18: 0.14010734 | AC18: 0.22341354 | AD18: 0.23712676
B19: van | C19: 0 | D19: 0 | E19: 0 | F19: 0 | G19: 0 | H19: 0 | I19: 0 | J19: 0 | K19: 0 | L19: 0 | M19: 0 | N19: 0 | O19: 0 | P19: 0 | Q19: 0 | R19: 0 | S19: 0 | T19: 0 | U19: 0 | V19: 0 | W19: 0 | X19: 0 | Y19: 0 | Z19: 0 | AA19: 0 | AB19: 0 | AC19: 0 | AD19: 0
B20: other | C20: 0 | D20: 0 | E20: 0 | F20: 0 | G20: 0 | H20: 0 | I20: 0 | J20: 0 | K20: 0 | L20: 0 | M20: 0 | N20: 0 | O20: 0 | P20: 0 | Q20: 0 | R20: 0 | S20: 0 | T20: 0 | U20: 0 | V20: 0 | W20: 0 | X20: 0 | Y20: 0 | Z20: 0 | AA20: 0 | AB20: 0 | AC20: 0 | AD20: 0
B21: taxi | C21: 0 | D21: 0 | E21: 0 | F21: 0 | G21: 0 | H21: 0 | I21: 0 | J21: 0 | K21: 0 | L21: 0 | M21: 0 | N21: 0 | O21: 0 | P21: 0 | Q21: 0 | R21: 0 | S21: 0 | T21: 0 | U21: 0 | V21: 0 | W21: 0 | X21: 0 | Y21: 0 | Z21: 0 | AA21: 0 | AB21: 0 | AC21: 0 | AD21: 0
B22: auto_rickshaw | C22: 0 | D22: 0 | E22: 0 | F22: 0 | G22: 0 | H22: 0 | I22: 0 | J22: 0 | K22: 0 | L22: 0 | M22: 0 | N22: 0 | O22: 0 | P22: 0 | Q22: 0 | R22: 0 | S22: 0 | T22: 0 | U22: 0 | V22: 0 | W22: 0 | X22: 0 | Y22: 0 | Z22: 0 | AA22: 0 | AB22: 0 | AC22: 0 | AD22: 0
A23: injury_reporting_rate | B23: constant | C23: 0.61011662 | D23: 0.9712732 | E23: 0.75207211 | F23: 0.75207211 | G23: 0.75207211 | H23: 0.9712732 | I23: 0.8982419 | J23: 0.87305122 | K23: 0.97949178 | L23: 0.95187122 | M23: 0.98497277 | N23: 0.8982419 | O23: 0.8982419 | P23: 0.98478261 | Q23: 0.87305122 | R23: 0.87305122 | S23: 0.87305122 | T23: 0.87305122 | U23: 0.87305122 | V23: 0.87305122 | W23: 0.87305122 | X23: 0.87305122 | Y23: 0.87305122 | Z23: 0.87305122 | AA23: 0.87305122 | AB23: 0.61011662 | AC23: 0.61011662 | AD23: 0.61011662
B24: alpha | C24: 3.0181604 | D24: 9.868747 | E24: 13.271038 | F24: 13.271038 | G24: 13.271038 | H24: 9.868747 | I24: 7.3119932 | J24: 8.8032185 | K24: 6.8907772 | L24: 16.491131 | M24: 4.8466218 | N24: 7.3119932 | O24: 7.3119932 | P24: 4.9183283 | Q24: 8.8032185 | R24: 8.8032185 | S24: 8.8032185 | T24: 8.8032185 | U24: 8.8032185 | V24: 8.8032185 | W24: 8.8032185 | X24: 8.8032185 | Y24: 8.8032185 | Z24: 8.8032185 | AA24: 8.8032185 | AB24: 5.8401537 | AC24: 5.8401537 | AD24: 3.0181604
B25: beta | C25: 1.9286978 | D25: 0.2918824 | E25: 4.3749268 | F25: 4.3749268 | G25: 4.3749268 | H25: 0.2918824 | I25: 0.82834534 | J25: 1.2800598 | K25: 0.14427644 | L25: 0.83382917 | M25: 0.073942442 | N25: 0.82834534 | O25: 0.82834534 | P25: 0.076000658 | Q25: 1.2800598 | R25: 1.2800598 | S25: 1.2800598 | T25: 1.2800598 | U25: 1.2800598 | V25: 1.2800598 | W25: 1.2800598 | X25: 1.2800598 | Y25: 1.2800598 | Z25: 1.2800598 | AA25: 1.2800598 | AB25: 3.7320388 | AC25: 3.7320388 | AD25: 1.9286978
A26: chronic_disease_scalar | B26: constant | C26: 1 | D26: 1 | E26: 1 | F26: 1 | G26: 1 | H26: 1 | I26: 1 | J26: 1 | K26: 1 | L26: 1 | M26: 1 | N26: 1 | O26: 1 | P26: 1 | Q26: 1 | R26: 1 | S26: 1 | T26: 1 | U26: 1 | V26: 1 | W26: 1 | X26: 1 | Y26: 1 | Z26: 1 | AA26: 1 | AB26: 1 | AC26: 1 | AD26: 1
B27: mean | C27: 1 | D27: 1 | E27: 1 | F27: 1 | G27: 1 | H27: 1 | I27: 1 | J27: 1 | K27: 1 | L27: 1 | M27: 1 | N27: 1 | O27: 1 | P27: 1 | Q27: 1 | R27: 1 | S27: 1 | T27: 1 | U27: 1 | V27: 1 | W27: 1 | X27: 1 | Y27: 1 | Z27: 1 | AA27: 1 | AB27: 1 | AC27: 1 | AD27: 1
B28: sd | C28: 1.2 | D28: 1.2 | E28: 1.2 | F28: 1.2 | G28: 1.2 | H28: 1.2 | I28: 1.2 | J28: 1.2 | K28: 1.2 | L28: 1.2 | M28: 1.2 | N28: 1.2 | O28: 1.2 | P28: 1.2 | Q28: 1.2 | R28: 1.2 | S28: 1.2 | T28: 1.2 | U28: 1.2 | V28: 1.2 | W28: 1.2 | X28: 1.2 | Y28: 1.2 | Z28: 1.2 | AA28: 1.2 | AB28: 1.2 | AC28: 1.2 | AD28: 1.2
A29: pm_conc_base | B29: constant | C29: 55 | D29: 28 | E29: 105 | F29: 32.38 | G29: 32.75 | H29: 17 | I29: 12.69 | J29: 32 | K29: 50 | L29: 14 | M29: 14.86 | N29: 21.09 | O29: 24.05 | P29: 15.575 | Q29: 10.492217 | R29: 12.561233 | S29: 15.604417 | T29: 13.883042 | U29: 11.6851 | V29: 38.09715 | W29: 26.3177 | X29: 21.8618 | Y29: 31.897407 | Z29: 34.446843 | AA29: 15.091033 | AB29: 5.91 | AC29: 10.79 | AD29: 14
B30: mean
B31: sd
A32: pm_trans_share | B32: constant | C32: 0.225 | D32: 0.4 | E32: 0.415 | F32: 0.281 | G32: 0.193 | H32: 0.18 | I32: 0.42 | J32: 0.31 | K32: 0.42 | L32: 0.32 | M32: 0.3111 | N32: 0.41 | O32: 0.41 | P32: 0.32 | Q32: 0.32 | R32: 0.32 | S32: 0.32 | T32: 0.32 | U32: 0.32 | V32: 0.32 | W32: 0.32 | X32: 0.32 | Y32: 0.32 | Z32: 0.32 | AA32: 0.32 | AB32: 0.225 | AC32: 0.225 | AD32: 0.225
B33: alpha
B34: beta
A35: background_pa_scalar | B35: constant | C35: 1 | D35: 1 | E35: 1 | F35: 1 | G35: 1 | H35: 1 | I35: 1 | J35: 1 | K35: 1 | L35: 1 | M35: 1 | N35: 1 | O35: 1 | P35: 1 | Q35: 1 | R35: 1 | S35: 1 | T35: 1 | U35: 1 | V35: 1 | W35: 1 | X35: 1 | Y35: 1 | Z35: 1 | AA35: 1 | AB35: 1 | AC35: 1 | AD35: 1
B36: mean | C36: 1 | D36: 1 | E36: 1 | F36: 1 | G36: 1 | H36: 1 | I36: 1 | J36: 1 | K36: 1 | L36: 1 | M36: 1 | N36: 1 | O36: 1 | P36: 1 | Q36: 1 | R36: 1 | S36: 1 | T36: 1 | U36: 1 | V36: 1 | W36: 1 | X36: 1 | Y36: 1 | Z36: 1 | AA36: 1 | AB36: 1 | AC36: 1 | AD36: 1
B37: sd | C37: 1.2 | D37: 1.2 | E37: 1.2 | F37: 1.2 | G37: 1.2 | H37: 1.2 | I37: 1.2 | J37: 1.2 | K37: 1.2 | L37: 1.2 | M37: 1.2 | N37: 1.2 | O37: 1.2 | P37: 1.2 | Q37: 1.2 | R37: 1.2 | S37: 1.2 | T37: 1.2 | U37: 1.2 | V37: 1.2 | W37: 1.2 | X37: 1.2 | Y37: 1.2 | Z37: 1.2 | AA37: 1.2 | AB37: 1.2 | AC37: 1.2 | AD37: 1.2
A38: bus_walk_time | B38: constant | C38: 12 | D38: 10 | E38: 15 | F38: 10 | G38: 12.5 | H38: 10 | I38: 16 | J38: 12 | K38: 10 | L38: 12 | M38: 12 | N38: 12 | O38: 12 | P38: 12 | Q38: 6 | R38: 6 | S38: 7 | T38: 8 | U38: 8 | V38: 7 | W38: 9 | X38: 6 | Y38: 7 | Z38: 8 | AA38: 8 | AB38: 16 | AC38: 10 | AD38: 10
B39: mean | C39: 8.1222313 | D39: 8.6662026 | E39: 12.549215 | F39: 6.4195823 | G39: 7.0932681 | H39: 7.1464217 | I39: 13.090641 | J39: 8.4119517 | K39: 8.032787 | L39: 8.4119517 | M39: 8.1222313 | N39: 8.4119517 | O39: 8.4119517 | P39: 8.4119517 | Q39: 5.1803641 | R39: 5.0279007 | S39: 5.8852037 | T39: 6.4507388 | U39: 4.2421697 | V39: 5.5871303 | W39: 7.5357398 | X39: 4.650155 | Y39: 5.7547474 | Z39: 6.7619 | AA39: 6.7849202 | AB39: 12.6159 | AC39: 7.8460414 | AD39: 8.6806411
B40: sd | C40: 2.4193954 | D40: 1.7075819 | E40: 1.8172314 | F40: 2.5638812 | G40: 2.8993953 | H40: 2.2698722 | I40: 1.8842831 | J40: 2.3231298 | K40: 1.9384653 | L40: 2.3231298 | M40: 2.4193954 | N40: 2.3231298 | O40: 2.3231298 | P40: 2.3231298 | Q40: 1.719449 | R40: 1.8122521 | S40: 1.8022107 | T40: 1.9273003 | U40: 3.0844724 | V40: 1.9571366 | W40: 1.8147218 | X40: 2.0420317 | Y40: 1.8699568 | Z40: 1.7858463 | AA40: 1.7753574 | AB40: 1.9925041 | AC40: 2.0067741 | AD40: 1.7022622
...

Sheet All_city_list
A1: List of parameters found in all_city_parameter_inputs | L1: Values that have been entered manually
L2: Values read in from other locations
A3: Location column | B3: Row location | C3: Default lookup | D3: Grouped sources lookup | E3: Location | F3: Parameter | G3: Detail | H3: Value | I3: Default value | J3: Classification | K3: Description | L3: Location of data (e.g. in v-drive, web link) | M3: Source of data | N3: Comments
A4: 3 | B4: 2 | C4: =IF(G4 = "",F4,IF(OR(G4="alpha",G4="beta",G4="constant",G4="sd",G4="mean",G4="sample"),F4,F4&" "&G4)) -> speeds auto_rickshaw | D4: =F4&"_"&E4 -> speeds_accra | E4: {=INDIRECT(ADDRESS(1,A4,1,1,"all_city_parameter_inputs"))} -> accra | F4: {=IF(AND(ISBLANK(INDIRECT(ADDRESS(B4,2,1,1,"all_city_parameter_inputs"))), ISBLANK(INDIRECT(ADDRESS(B4,1,1,1,"all_city_parameter_inputs")))), "", IF(ISBLANK(INDIRECT(ADDRESS(B4,1,1,1,"all_city_parameter_inputs"))), All_city_list!F3,INDIRECT(ADDRESS(B4,1,1,1,"all_city_parameter_inputs"))))} -> speeds | G4: {=IF(AND(ISBLANK(INDIRECT(ADDRESS(B4,3,1,1,"all_city_parameter_inputs"))),ISBLANK(INDIRECT(ADDRESS(B4,2,1,1,"all_city_parameter_inputs")))),"",IF(ISBLANK(INDIRECT(ADDRESS(B4,2,1,1,"all_city_parameter_inputs"))),"",INDIRECT(ADDRESS(B4,2,1,1,"all_city_parameter_inputs"))))} -> auto_rickshaw | H4: {=IF(ISBLANK(INDIRECT(ADDRESS(B4,A4,1,1,"all_city_parameter_inputs"))), "--",INDIRECT(ADDRESS(B4,A4,1,1,"all_city_parameter_inputs")))} -> 4 | I4: =IF(OR(G4="alpha",G4="beta",G4="sd",G4="mean"),"--",VLOOKUP(C4,Default!$B$5:$H$113,7,FALSE)) -> 0 | J4: =VLOOKUP(F4,Lookup!$C$5:$D$109,2, FALSE) -> Travel values | K4: =VLOOKUP(C4,Default!$B$4:$E$113,4, FALSE) -> 0 | L4: VehicleSpeeds_Summary_vxxx.docx on OneDrive Ali Abbas - ITHIM Global\Methods and Processes\Input Parameters\VehicleSpeeds
A5: 3 | B5: 3 | C5: =IF(G5 = "",F5,IF(OR(G5="alpha",G5="beta",G5="constant",G5="sd",G5="mean",G5="sample"),F5,F5&" "&G5)) -> speeds bus | D5: =F5&"_"&E5 -> speeds_accra | E5: {=INDIRECT(ADDRESS(1,A5,1,1,"all_city_parameter_inputs"))} -> accra | F5: {=IF(AND(ISBLANK(INDIRECT(ADDRESS(B5,2,1,1,"all_city_parameter_inputs"))), ISBLANK(INDIRECT(ADDRESS(B5,1,1,1,"all_city_parameter_inputs")))), "", IF(ISBLANK(INDIRECT(ADDRESS(B5,1,1,1,"all_city_parameter_inputs"))), All_city_list!F4,INDIRECT(ADDRESS(B5,1,1,1,"all_city_parameter_inputs"))))} -> speeds | G5: {=IF(AND(ISBLANK(INDIRECT(ADDRESS(B5,3,1,1,"all_city_parameter_inputs"))),ISBLANK(INDIRECT(ADDRESS(B5,2,1,1,"all_city_parameter_inputs")))),"",IF(ISBLANK(INDIRECT(ADDRESS(B5,2,1,1,"all_city_parameter_inputs"))),"",INDIRECT(ADDRESS(B5,2,1,1,"all_city_parameter_inputs"))))} -> bus | H5: {=IF(ISBLANK(INDIRECT(ADDRESS(B5,A5,1,1,"all_city_parameter_inputs"))), "--",INDIRECT(ADDRESS(B5,A5,1,1,"all_city_parameter_inputs")))} -> 12 | I5: =IF(OR(G5="alpha",G5="beta",G5="sd",G5="mean"),"--",VLOOKUP(C5,Default!$B$5:$H$113,7,FALSE)) -> 8.1 | J5: =VLOOKUP(F5,Lookup!$C$5:$D$109,2, FALSE) -> Travel values | K5: =VLOOKUP(C5,Default!$B$4:$E$113,4, FALSE) -> - Speeds in km/h used for different vehicle categories - It is used in "add_ghost_trips" to add new trips taken by no one. - It is used to complete trip distance and duration (function "complete_trip_distance_duration"). - It us used to recompute distances when reassigning new trips for scenarios (function "create_cycle_scenarios", "create_max_mode_share_scenarios", "create_scenario") | L5: {=IF(ISNA(VLOOKUP(D5,Grouped_Sources!$C:$C,1,FALSE)),"", INDIRECT(VLOOKUP(D5,Grouped_Sources!$C:$G,5,FALSE)))} -> VehicleSpeeds_Summary_vxxx.docx on OneDrive Ali Abbas - ITHIM Global\Methods and Processes\Input Parameters\VehicleSpeeds
A6: 3 | B6: 4 | C6: =IF(G6 = "",F6,IF(OR(G6="alpha",G6="beta",G6="constant",G6="sd",G6="mean",G6="sample"),F6,F6&" "&G6)) -> speeds car | D6: =F6&"_"&E6 -> speeds_accra | E6: {=INDIRECT(ADDRESS(1,A6,1,1,"all_city_parameter_inputs"))} -> accra | F6: {=IF(AND(ISBLANK(INDIRECT(ADDRESS(B6,2,1,1,"all_city_parameter_inputs"))), ISBLANK(INDIRECT(ADDRESS(B6,1,1,1,"all_city_parameter_inputs")))), "", IF(ISBLANK(INDIRECT(ADDRESS(B6,1,1,1,"all_city_parameter_inputs"))), All_city_list!F5,INDIRECT(ADDRESS(B6,1,1,1,"all_city_parameter_inputs"))))} -> speeds | G6: {=IF(AND(ISBLANK(INDIRECT(ADDRESS(B6,3,1,1,"all_city_parameter_inputs"))),ISBLANK(INDIRECT(ADDRESS(B6,2,1,1,"all_city_parameter_inputs")))),"",IF(ISBLANK(INDIRECT(ADDRESS(B6,2,1,1,"all_city_parameter_inputs"))),"",INDIRECT(ADDRESS(B6,2,1,1,"all_city_parameter_inputs"))))} -> car | H6: {=IF(ISBLANK(INDIRECT(ADDRESS(B6,A6,1,1,"all_city_parameter_inputs"))), "--",INDIRECT(ADDRESS(B6,A6,1,1,"all_city_parameter_inputs")))} -> 15 | I6: =IF(OR(G6="alpha",G6="beta",G6="sd",G6="mean"),"--",VLOOKUP(C6,Default!$B$5:$H$113,7,FALSE)) -> 13.8 | J6: =VLOOKUP(F6,Lookup!$C$5:$D$109,2, FALSE) -> Travel values | K6: =VLOOKUP(C6,Default!$B$4:$E$113,4, FALSE) -> 0 | L6: {=IF(ISNA(VLOOKUP(D6,Grouped_Sources!$C:$C,1,FALSE)),"", INDIRECT(VLOOKUP(D6,Grouped_Sources!$C:$G,5,FALSE)))} -> VehicleSpeeds_Summary_vxxx.docx on OneDrive Ali Abbas - ITHIM Global\Methods and Processes\Input Parameters\VehicleSpeeds
A7: 3 | B7: 5 | C7: =IF(G7 = "",F7,IF(OR(G7="alpha",G7="beta",G7="constant",G7="sd",G7="mean",G7="sample"),F7,F7&" "&G7)) -> speeds cycle | D7: =F7&"_"&E7 -> speeds_accra | E7: {=INDIRECT(ADDRESS(1,A7,1,1,"all_city_parameter_inputs"))} -> accra | F7: {=IF(AND(ISBLANK(INDIRECT(ADDRESS(B7,2,1,1,"all_city_parameter_inputs"))), ISBLANK(INDIRECT(ADDRESS(B7,1,1,1,"all_city_parameter_inputs")))), "", IF(ISBLANK(INDIRECT(ADDRESS(B7,1,1,1,"all_city_parameter_inputs"))), All_city_list!F6,INDIRECT(ADDRESS(B7,1,1,1,"all_city_parameter_inputs"))))} -> speeds | G7: {=IF(AND(ISBLANK(INDIRECT(ADDRESS(B7,3,1,1,"all_city_parameter_inputs"))),ISBLANK(INDIRECT(ADDRESS(B7,2,1,1,"all_city_parameter_inputs")))),"",IF(ISBLANK(INDIRECT(ADDRESS(B7,2,1,1,"all_city_parameter_inputs"))),"",INDIRECT(ADDRESS(B7,2,1,1,"all_city_parameter_inputs"))))} -> cycle | H7: {=IF(ISBLANK(INDIRECT(ADDRESS(B7,A7,1,1,"all_city_parameter_inputs"))), "--",INDIRECT(ADDRESS(B7,A7,1,1,"all_city_parameter_inputs")))} -> 6 | I7: =IF(OR(G7="alpha",G7="beta",G7="sd",G7="mean"),"--",VLOOKUP(C7,Default!$B$5:$H$113,7,FALSE)) -> 7.2 | J7: =VLOOKUP(F7,Lookup!$C$5:$D$109,2, FALSE) -> Travel values | K7: =VLOOKUP(C7,Default!$B$4:$E$113,4, FALSE) -> 0 | L7: {=IF(ISNA(VLOOKUP(D7,Grouped_Sources!$C:$C,1,FALSE)),"", INDIRECT(VLOOKUP(D7,Grouped_Sources!$C:$G,5,FALSE)))} -> VehicleSpeeds_Summary_vxxx.docx on OneDrive Ali Abbas - ITHIM Global\Methods and Processes\Input Parameters\VehicleSpeeds
A8: 3 | B8: 6 | C8: =IF(G8 = "",F8,IF(OR(G8="alpha",G8="beta",G8="constant",G8="sd",G8="mean",G8="sample"),F8,F8&" "&G8)) -> speeds subway | D8: =F8&"_"&E8 -> speeds_accra | E8: {=INDIRECT(ADDRESS(1,A8,1,1,"all_city_parameter_inputs"))} -> accra | F8: {=IF(AND(ISBLANK(INDIRECT(ADDRESS(B8,2,1,1,"all_city_parameter_inputs"))), ISBLANK(INDIRECT(ADDRESS(B8,1,1,1,"all_city_parameter_inputs")))), "", IF(ISBLANK(INDIRECT(ADDRESS(B8,1,1,1,"all_city_parameter_inputs"))), All_city_list!F7,INDIRECT(ADDRESS(B8,1,1,1,"all_city_parameter_inputs"))))} -> speeds | G8: {=IF(AND(ISBLANK(INDIRECT(ADDRESS(B8,3,1,1,"all_city_parameter_inputs"))),ISBLANK(INDIRECT(ADDRESS(B8,2,1,1,"all_city_parameter_inputs")))),"",IF(ISBLANK(INDIRECT(ADDRESS(B8,2,1,1,"all_city_parameter_inputs"))),"",INDIRECT(ADDRESS(B8,2,1,1,"all_city_parameter_inputs"))))} -> subway | H8: {=IF(ISBLANK(INDIRECT(ADDRESS(B8,A8,1,1,"all_city_parameter_inputs"))), "--",INDIRECT(ADDRESS(B8,A8,1,1,"all_city_parameter_inputs")))} -> -- | I8: =IF(OR(G8="alpha",G8="beta",G8="sd",G8="mean"),"--",VLOOKUP(C8,Default!$B$5:$H$113,7,FALSE)) -> 18.1 | J8: =VLOOKUP(F8,Lookup!$C$5:$D$109,2, FALSE) -> Travel values | K8: =VLOOKUP(C8,Default!$B$4:$E$113,4, FALSE) -> 0 | L8: {=IF(ISNA(VLOOKUP(D8,Grouped_Sources!$C:$C,1,FALSE)),"", INDIRECT(VLOOKUP(D8,Grouped_Sources!$C:$G,5,FALSE)))} -> VehicleSpeeds_Summary_vxxx.docx on OneDrive Ali Abbas - ITHIM Global\Methods and Processes\Input Parameters\VehicleSpeeds
A9: 3 | B9: 7 | C9: =IF(G9 = "",F9,IF(OR(G9="alpha",G9="beta",G9="constant",G9="sd",G9="mean",G9="sample"),F9,F9&" "&G9)) -> speeds motorcycle | D9: =F9&"_"&E9 -> speeds_accra | E9: {=INDIRECT(ADDRESS(1,A9,1,1,"all_city_parameter_inputs"))} -> accra | F9: {=IF(AND(ISBLANK(INDIRECT(ADDRESS(B9,2,1,1,"all_city_parameter_inputs"))), ISBLANK(INDIRECT(ADDRESS(B9,1,1,1,"all_city_parameter_inputs")))), "", IF(ISBLANK(INDIRECT(ADDRESS(B9,1,1,1,"all_city_parameter_inputs"))), All_city_list!F8,INDIRECT(ADDRESS(B9,1,1,1,"all_city_parameter_inputs"))))} -> speeds | G9: {=IF(AND(ISBLANK(INDIRECT(ADDRESS(B9,3,1,1,"all_city_parameter_inputs"))),ISBLANK(INDIRECT(ADDRESS(B9,2,1,1,"all_city_parameter_inputs")))),"",IF(ISBLANK(INDIRECT(ADDRESS(B9,2,1,1,"all_city_parameter_inputs"))),"",INDIRECT(ADDRESS(B9,2,1,1,"all_city_parameter_inputs"))))} -> motorcycle | H9: {=IF(ISBLANK(INDIRECT(ADDRESS(B9,A9,1,1,"all_city_parameter_inputs"))), "--",INDIRECT(ADDRESS(B9,A9,1,1,"all_city_parameter_inputs")))} -> 15 | I9: =IF(OR(G9="alpha",G9="beta",G9="sd",G9="mean"),"--",VLOOKUP(C9,Default!$B$5:$H$113,7,FALSE)) -> 15.2 | J9: =VLOOKUP(F9,Lookup!$C$5:$D$109,2, FALSE) -> Travel values | K9: =VLOOKUP(C9,Default!$B$4:$E$113,4, FALSE) -> 0 | L9: {=IF(ISNA(VLOOKUP(D9,Grouped_Sources!$C:$C,1,FALSE)),"", INDIRECT(VLOOKUP(D9,Grouped_Sources!$C:$G,5,FALSE)))} -> VehicleSpeeds_Summary_vxxx.docx on OneDrive Ali Abbas - ITHIM Global\Methods and Processes\Input Parameters\VehicleSpeeds
A10: 3 | B10: 8 | C10: =IF(G10 = "",F10,IF(OR(G10="alpha",G10="beta",G10="constant",G10="sd",G10="mean",G10="sample"),F10,F10&" "&G10)) -> speeds other | D10: =F10&"_"&E10 -> speeds_accra | E10: {=INDIRECT(ADDRESS(1,A10,1,1,"all_city_parameter_inputs"))} -> accra | F10: {=IF(AND(ISBLANK(INDIRECT(ADDRESS(B10,2,1,1,"all_city_parameter_inputs"))), ISBLANK(INDIRECT(ADDRESS(B10,1,1,1,"all_city_parameter_inputs")))), "", IF(ISBLANK(INDIRECT(ADDRESS(B10,1,1,1,"all_city_parameter_inputs"))), All_city_list!F9,INDIRECT(ADDRESS(B10,1,1,1,"all_city_parameter_inputs"))))} -> speeds | G10: {=IF(AND(ISBLANK(INDIRECT(ADDRESS(B10,3,1,1,"all_city_parameter_inputs"))),ISBLANK(INDIRECT(ADDRESS(B10,2,1,1,"all_city_parameter_inputs")))),"",IF(ISBLANK(INDIRECT(ADDRESS(B10,2,1,1,"all_city_parameter_inputs"))),"",INDIRECT(ADDRESS(B10,2,1,1,"all_city_parameter_inputs"))))} -> other | H10: {=IF(ISBLANK(INDIRECT(ADDRESS(B10,A10,1,1,"all_city_parameter_inputs"))), "--",INDIRECT(ADDRESS(B10,A10,1,1,"all_city_parameter_inputs")))} -> -- | I10: =IF(OR(G10="alpha",G10="beta",G10="sd",G10="mean"),"--",VLOOKUP(C10,Default!$B$5:$H$113,7,FALSE)) -> 9.1 | J10: =VLOOKUP(F10,Lookup!$C$5:$D$109,2, FALSE) -> Travel values | K10: =VLOOKUP(C10,Default!$B$4:$E$113,4, FALSE) -> 0 | L10: {=IF(ISNA(VLOOKUP(D10,Grouped_Sources!$C:$C,1,FALSE)),"", INDIRECT(VLOOKUP(D10,Grouped_Sources!$C:$G,5,FALSE)))} -> VehicleSpeeds_Summary_vxxx.docx on OneDrive Ali Abbas - ITHIM Global\Methods and Processes\Input Parameters\VehicleSpeeds
A11: 3 | B11: 9 | C11: =IF(G11 = "",F11,IF(OR(G11="alpha",G11="beta",G11="constant",G11="sd",G11="mean",G11="sample"),F11,F11&" "&G11)) -> speeds pedestrian | D11: =F11&"_"&E11 -> speeds_accra | E11: {=INDIRECT(ADDRESS(1,A11,1,1,"all_city_parameter_inputs"))} -> accra | F11: {=IF(AND(ISBLANK(INDIRECT(ADDRESS(B11,2,1,1,"all_city_parameter_inputs"))), ISBLANK(INDIRECT(ADDRESS(B11,1,1,1,"all_city_parameter_inputs")))), "", IF(ISBLANK(INDIRECT(ADDRESS(B11,1,1,1,"all_city_parameter_inputs"))), All_city_list!F10,INDIRECT(ADDRESS(B11,1,1,1,"all_city_parameter_inputs"))))} -> speeds | G11: {=IF(AND(ISBLANK(INDIRECT(ADDRESS(B11,3,1,1,"all_city_parameter_inputs"))),ISBLANK(INDIRECT(ADDRESS(B11,2,1,1,"all_city_parameter_inputs")))),"",IF(ISBLANK(INDIRECT(ADDRESS(B11,2,1,1,"all_city_parameter_inputs"))),"",INDIRECT(ADDRESS(B11,2,1,1,"all_city_parameter_inputs"))))} -> pedestrian | H11: {=IF(ISBLANK(INDIRECT(ADDRESS(B11,A11,1,1,"all_city_parameter_inputs"))), "--",INDIRECT(ADDRESS(B11,A11,1,1,"all_city_parameter_inputs")))} -> 2 | I11: =IF(OR(G11="alpha",G11="beta",G11="sd",G11="mean"),"--",VLOOKUP(C11,Default!$B$5:$H$113,7,FALSE)) -> 0 | J11: =VLOOKUP(F11,Lookup!$C$5:$D$109,2, FALSE) -> Travel values | K11: =VLOOKUP(C11,Default!$B$4:$E$113,4, FALSE) -> 0 | L11: {=IF(ISNA(VLOOKUP(D11,Grouped_Sources!$C:$C,1,FALSE)),"", INDIRECT(VLOOKUP(D11,Grouped_Sources!$C:$G,5,FALSE)))} -> VehicleSpeeds_Summary_vxxx.docx on OneDrive Ali Abbas - ITHIM Global\Methods and Processes\Input Parameters\VehicleSpeeds
A12: 3 | B12: 10 | C12: =IF(G12 = "",F12,IF(OR(G12="alpha",G12="beta",G12="constant",G12="sd",G12="mean",G12="sample"),F12,F12&" "&G12)) -> speeds rail | D12: =F12&"_"&E12 -> speeds_accra | E12: {=INDIRECT(ADDRESS(1,A12,1,1,"all_city_parameter_inputs"))} -> accra | F12: {=IF(AND(ISBLANK(INDIRECT(ADDRESS(B12,2,1,1,"all_city_parameter_inputs"))), ISBLANK(INDIRECT(ADDRESS(B12,1,1,1,"all_city_parameter_inputs")))), "", IF(ISBLANK(INDIRECT(ADDRESS(B12,1,1,1,"all_city_parameter_inputs"))), All_city_list!F11,INDIRECT(ADDRESS(B12,1,1,1,"all_city_parameter_inputs"))))} -> speeds | G12: {=IF(AND(ISBLANK(INDIRECT(ADDRESS(B12,3,1,1,"all_city_parameter_inputs"))),ISBLANK(INDIRECT(ADDRESS(B12,2,1,1,"all_city_parameter_inputs")))),"",IF(ISBLANK(INDIRECT(ADDRESS(B12,2,1,1,"all_city_parameter_inputs"))),"",INDIRECT(ADDRESS(B12,2,1,1,"all_city_parameter_inputs"))))} -> rail | H12: {=IF(ISBLANK(INDIRECT(ADDRESS(B12,A12,1,1,"all_city_parameter_inputs"))), "--",INDIRECT(ADDRESS(B12,A12,1,1,"all_city_parameter_inputs")))} -> 20.6 | I12: =IF(OR(G12="alpha",G12="beta",G12="sd",G12="mean"),"--",VLOOKUP(C12,Default!$B$5:$H$113,7,FALSE)) -> 21.9 | J12: =VLOOKUP(F12,Lookup!$C$5:$D$109,2, FALSE) -> Travel values | K12: =VLOOKUP(C12,Default!$B$4:$E$113,4, FALSE) -> 0 | L12: {=IF(ISNA(VLOOKUP(D12,Grouped_Sources!$C:$C,1,FALSE)),"", INDIRECT(VLOOKUP(D12,Grouped_Sources!$C:$G,5,FALSE)))} -> VehicleSpeeds_Summary_vxxx.docx on OneDrive Ali Abbas - ITHIM Global\Methods and Processes\Input Parameters\VehicleSpeeds
A13: 3 | B13: 11 | C13: =IF(G13 = "",F13,IF(OR(G13="alpha",G13="beta",G13="constant",G13="sd",G13="mean",G13="sample"),F13,F13&" "&G13)) -> speeds taxi | D13: =F13&"_"&E13 -> speeds_accra | E13: {=INDIRECT(ADDRESS(1,A13,1,1,"all_city_parameter_inputs"))} -> accra | F13: {=IF(AND(ISBLANK(INDIRECT(ADDRESS(B13,2,1,1,"all_city_parameter_inputs"))), ISBLANK(INDIRECT(ADDRESS(B13,1,1,1,"all_city_parameter_inputs")))), "", IF(ISBLANK(INDIRECT(ADDRESS(B13,1,1,1,"all_city_parameter_inputs"))), All_city_list!F12,INDIRECT(ADDRESS(B13,1,1,1,"all_city_parameter_inputs"))))} -> speeds | G13: {=IF(AND(ISBLANK(INDIRECT(ADDRESS(B13,3,1,1,"all_city_parameter_inputs"))),ISBLANK(INDIRECT(ADDRESS(B13,2,1,1,"all_city_parameter_inputs")))),"",IF(ISBLANK(INDIRECT(ADDRESS(B13,2,1,1,"all_city_parameter_inputs"))),"",INDIRECT(ADDRESS(B13,2,1,1,"all_city_parameter_inputs"))))} -> taxi | H13: {=IF(ISBLANK(INDIRECT(ADDRESS(B13,A13,1,1,"all_city_parameter_inputs"))), "--",INDIRECT(ADDRESS(B13,A13,1,1,"all_city_parameter_inputs")))} -> 12 | I13: =IF(OR(G13="alpha",G13="beta",G13="sd",G13="mean"),"--",VLOOKUP(C13,Default!$B$5:$H$113,7,FALSE)) -> 13.8 | J13: =VLOOKUP(F13,Lookup!$C$5:$D$109,2, FALSE) -> Travel values | K13: =VLOOKUP(C13,Default!$B$4:$E$113,4, FALSE) -> 0 | L13: {=IF(ISNA(VLOOKUP(D13,Grouped_Sources!$C:$C,1,FALSE)),"", INDIRECT(VLOOKUP(D13,Grouped_Sources!$C:$G,5,FALSE)))} -> VehicleSpeeds_Summary_vxxx.docx on OneDrive Ali Abbas - ITHIM Global\Methods and Processes\Input Parameters\VehicleSpeeds
A14: 3 | B14: 12 | C14: =IF(G14 = "",F14,IF(OR(G14="alpha",G14="beta",G14="constant",G14="sd",G14="mean",G14="sample"),F14,F14&" "&G14)) -> speeds truck | D14: =F14&"_"&E14 -> speeds_accra | E14: {=INDIRECT(ADDRESS(1,A14,1,1,"all_city_parameter_inputs"))} -> accra | F14: {=IF(AND(ISBLANK(INDIRECT(ADDRESS(B14,2,1,1,"all_city_parameter_inputs"))), ISBLANK(INDIRECT(ADDRESS(B14,1,1,1,"all_city_parameter_inputs")))), "", IF(ISBLANK(INDIRECT(ADDRESS(B14,1,1,1,"all_city_parameter_inputs"))), All_city_list!F13,INDIRECT(ADDRESS(B14,1,1,1,"all_city_parameter_inputs"))))} -> speeds | G14: {=IF(AND(ISBLANK(INDIRECT(ADDRESS(B14,3,1,1,"all_city_parameter_inputs"))),ISBLANK(INDIRECT(ADDRESS(B14,2,1,1,"all_city_parameter_inputs")))),"",IF(ISBLANK(INDIRECT(ADDRESS(B14,2,1,1,"all_city_parameter_inputs"))),"",INDIRECT(ADDRESS(B14,2,1,1,"all_city_parameter_inputs"))))} -> truck | H14: {=IF(ISBLANK(INDIRECT(ADDRESS(B14,A14,1,1,"all_city_parameter_inputs"))), "--",INDIRECT(ADDRESS(B14,A14,1,1,"all_city_parameter_inputs")))} -> 12 | I14: =IF(OR(G14="alpha",G14="beta",G14="sd",G14="mean"),"--",VLOOKUP(C14,Default!$B$5:$H$113,7,FALSE)) -> 8.1 | J14: =VLOOKUP(F14,Lookup!$C$5:$D$109,2, FALSE) -> Travel values | K14: =VLOOKUP(C14,Default!$B$4:$E$113,4, FALSE) -> 0 | L14: {=IF(ISNA(VLOOKUP(D14,Grouped_Sources!$C:$C,1,FALSE)),"", INDIRECT(VLOOKUP(D14,Grouped_Sources!$C:$G,5,FALSE)))} -> VehicleSpeeds_Summary_vxxx.docx on OneDrive Ali Abbas - ITHIM Global\Methods and Processes\Input Parameters\VehicleSpeeds
A15: 3 | B15: 13 | C15: =IF(G15 = "",F15,IF(OR(G15="alpha",G15="beta",G15="constant",G15="sd",G15="mean",G15="sample"),F15,F15&" "&G15)) -> speeds van | D15: =F15&"_"&E15 -> speeds_accra | E15: {=INDIRECT(ADDRESS(1,A15,1,1,"all_city_parameter_inputs"))} -> accra | F15: {=IF(AND(ISBLANK(INDIRECT(ADDRESS(B15,2,1,1,"all_city_parameter_inputs"))), ISBLANK(INDIRECT(ADDRESS(B15,1,1,1,"all_city_parameter_inputs")))), "", IF(ISBLANK(INDIRECT(ADDRESS(B15,1,1,1,"all_city_parameter_inputs"))), All_city_list!F14,INDIRECT(ADDRESS(B15,1,1,1,"all_city_parameter_inputs"))))} -> speeds | G15: {=IF(AND(ISBLANK(INDIRECT(ADDRESS(B15,3,1,1,"all_city_parameter_inputs"))),ISBLANK(INDIRECT(ADDRESS(B15,2,1,1,"all_city_parameter_inputs")))),"",IF(ISBLANK(INDIRECT(ADDRESS(B15,2,1,1,"all_city_parameter_inputs"))),"",INDIRECT(ADDRESS(B15,2,1,1,"all_city_parameter_inputs"))))} -> van | H15: {=IF(ISBLANK(INDIRECT(ADDRESS(B15,A15,1,1,"all_city_parameter_inputs"))), "--",INDIRECT(ADDRESS(B15,A15,1,1,"all_city_parameter_inputs")))} -> 15 | I15: =IF(OR(G15="alpha",G15="beta",G15="sd",G15="mean"),"--",VLOOKUP(C15,Default!$B$5:$H$113,7,FALSE)) -> 0 | J15: =VLOOKUP(F15,Lookup!$C$5:$D$109,2, FALSE) -> Travel values | K15: =VLOOKUP(C15,Default!$B$4:$E$113,4, FALSE) -> 0 | L15: {=IF(ISNA(VLOOKUP(D15,Grouped_Sources!$C:$C,1,FALSE)),"", INDIRECT(VLOOKUP(D15,Grouped_Sources!$C:$G,5,FALSE)))} -> VehicleSpeeds_Summary_vxxx.docx on OneDrive Ali Abbas - ITHIM Global\Methods and Processes\Input Parameters\VehicleSpeeds
A16: 3 | B16: 14 | C16: =IF(G16 = "",F16,IF(OR(G16="alpha",G16="beta",G16="constant",G16="sd",G16="mean",G16="sample"),F16,F16&" "&G16)) -> PM_emission_inventories motorcycle | D16: =F16&"_"&E16 -> PM_emission_inventories_accra | E16: {=INDIRECT(ADDRESS(1,A16,1,1,"all_city_parameter_inputs"))} -> accra | F16: {=IF(AND(ISBLANK(INDIRECT(ADDRESS(B16,2,1,1,"all_city_parameter_inputs"))), ISBLANK(INDIRECT(ADDRESS(B16,1,1,1,"all_city_parameter_inputs")))), "", IF(ISBLANK(INDIRECT(ADDRESS(B16,1,1,1,"all_city_parameter_inputs"))), All_city_list!F5,INDIRECT(ADDRESS(B16,1,1,1,"all_city_parameter_inputs"))))} -> PM_emission_inventories | G16: {=IF(AND(ISBLANK(INDIRECT(ADDRESS(B16,3,1,1,"all_city_parameter_inputs"))),ISBLANK(INDIRECT(ADDRESS(B16,2,1,1,"all_city_parameter_inputs")))),"",IF(ISBLANK(INDIRECT(ADDRESS(B16,2,1,1,"all_city_parameter_inputs"))),"",INDIRECT(ADDRESS(B16,2,1,1,"all_city_parameter_inputs"))))} -> motorcycle | H16: {=IF(ISBLANK(INDIRECT(ADDRESS(B16,A16,1,1,"all_city_parameter_inputs"))), "--",INDIRECT(ADDRESS(B16,A16,1,1,"all_city_parameter_inputs")))} -> 0.002436234 | I16: =IF(OR(G16="alpha",G16="beta",G16="sd",G16="mean"),"--",VLOOKUP(C16,Default!$B$5:$H$113,7,FALSE)) -> 0.0023031654 | J16: =VLOOKUP(F16,Lookup!$C$5:$D$109,2, FALSE) -> Pollution values | K16: =VLOOKUP(C16,Default!$B$4:$E$113,4, FALSE) -> - Used to estimate the PM for scenarios (function "scenario_pm_calculations"). - used as reference to compute confidence around it (function "ithim_setup_parameters"). - used to create VEHICLE_INVENTORY, with speeds, PM and CO2 emissions (function "set_vehicle_inventory"). | L16: air pollution and CO2 write-up_only table_V4.docx (dropbox.com) | M16: EDGAR and various other sources, detailed in document | N16: NEEDS updating with OneDrive link!!!!
A17: 3 | B17: 15 | C17: =IF(G17 = "",F17,IF(OR(G17="alpha",G17="beta",G17="constant",G17="sd",G17="mean",G17="sample"),F17,F17&" "&G17)) -> PM_emission_inventories car | D17: =F17&"_"&E17 -> PM_emission_inventories_accra | E17: {=INDIRECT(ADDRESS(1,A17,1,1,"all_city_parameter_inputs"))} -> accra | F17: {=IF(AND(ISBLANK(INDIRECT(ADDRESS(B17,2,1,1,"all_city_parameter_inputs"))), ISBLANK(INDIRECT(ADDRESS(B17,1,1,1,"all_city_parameter_inputs")))), "", IF(ISBLANK(INDIRECT(ADDRESS(B17,1,1,1,"all_city_parameter_inputs"))), All_city_list!F16,INDIRECT(ADDRESS(B17,1,1,1,"all_city_parameter_inputs"))))} -> PM_emission_inventories | G17: {=IF(AND(ISBLANK(INDIRECT(ADDRESS(B17,3,1,1,"all_city_parameter_inputs"))),ISBLANK(INDIRECT(ADDRESS(B17,2,1,1,"all_city_parameter_inputs")))),"",IF(ISBLANK(INDIRECT(ADDRESS(B17,2,1,1,"all_city_parameter_inputs"))),"",INDIRECT(ADDRESS(B17,2,1,1,"all_city_parameter_inputs"))))} -> car | H17: {=IF(ISBLANK(INDIRECT(ADDRESS(B17,A17,1,1,"all_city_parameter_inputs"))), "--",INDIRECT(ADDRESS(B17,A17,1,1,"all_city_parameter_inputs")))} -> 0.5899859 | I17: =IF(OR(G17="alpha",G17="beta",G17="sd",G17="mean"),"--",VLOOKUP(C17,Default!$B$5:$H$113,7,FALSE)) -> 0.081980353 | J17: =VLOOKUP(F17,Lookup!$C$5:$D$109,2, FALSE) -> Pollution values | K17: =VLOOKUP(C17,Default!$B$4:$E$113,4, FALSE) -> 0 | L17: {=IF(ISNA(VLOOKUP(D17,Grouped_Sources!$C:$C,1,FALSE)),"", INDIRECT(VLOOKUP(D17,Grouped_Sources!$C:$G,5,FALSE)))} -> air pollution and CO2 write-up_only table_V4.docx (dropbox.com)
A18: 3 | B18: 16 | C18: =IF(G18 = "",F18,IF(OR(G18="alpha",G18="beta",G18="constant",G18="sd",G18="mean",G18="sample"),F18,F18&" "&G18)) -> PM_emission_inventories bus_driver | D18: =F18&"_"&E18 -> PM_emission_inventories_accra | E18: {=INDIRECT(ADDRESS(1,A18,1,1,"all_city_parameter_inputs"))} -> accra | F18: {=IF(AND(ISBLANK(INDIRECT(ADDRESS(B18,2,1,1,"all_city_parameter_inputs"))), ISBLANK(INDIRECT(ADDRESS(B18,1,1,1,"all_city_parameter_inputs")))), "", IF(ISBLANK(INDIRECT(ADDRESS(B18,1,1,1,"all_city_parameter_inputs"))), All_city_list!F17,INDIRECT(ADDRESS(B18,1,1,1,"all_city_parameter_inputs"))))} -> PM_emission_inventories | G18: {=IF(AND(ISBLANK(INDIRECT(ADDRESS(B18,3,1,1,"all_city_parameter_inputs"))),ISBLANK(INDIRECT(ADDRESS(B18,2,1,1,"all_city_parameter_inputs")))),"",IF(ISBLANK(INDIRECT(ADDRESS(B18,2,1,1,"all_city_parameter_inputs"))),"",INDIRECT(ADDRESS(B18,2,1,1,"all_city_parameter_inputs"))))} -> bus_driver | H18: {=IF(ISBLANK(INDIRECT(ADDRESS(B18,A18,1,1,"all_city_parameter_inputs"))), "--",INDIRECT(ADDRESS(B18,A18,1,1,"all_city_parameter_inputs")))} -> 0.04993458 | I18: =IF(OR(G18="alpha",G18="beta",G18="sd",G18="mean"),"--",VLOOKUP(C18,Default!$B$5:$H$113,7,FALSE)) -> 0.12246677 | J18: =VLOOKUP(F18,Lookup!$C$5:$D$109,2, FALSE) -> Pollution values | K18: =VLOOKUP(C18,Default!$B$4:$E$113,4, FALSE) -> 0 | L18: {=IF(ISNA(VLOOKUP(D18,Grouped_Sources!$C:$C,1,FALSE)),"", INDIRECT(VLOOKUP(D18,Grouped_Sources!$C:$G,5,FALSE)))} -> air pollution and CO2 write-up_only table_V4.docx (dropbox.com)
A19: 3 | B19: 17 | C19: =IF(G19 = "",F19,IF(OR(G19="alpha",G19="beta",G19="constant",G19="sd",G19="mean",G19="sample"),F19,F19&" "&G19)) -> PM_emission_inventories big_truck | D19: =F19&"_"&E19 -> PM_emission_inventories_accra | E19: {=INDIRECT(ADDRESS(1,A19,1,1,"all_city_parameter_inputs"))} -> accra | F19: {=IF(AND(ISBLANK(INDIRECT(ADDRESS(B19,2,1,1,"all_city_parameter_inputs"))), ISBLANK(INDIRECT(ADDRESS(B19,1,1,1,"all_city_parameter_inputs")))), "", IF(ISBLANK(INDIRECT(ADDRESS(B19,1,1,1,"all_city_parameter_inputs"))), All_city_list!F18,INDIRECT(ADDRESS(B19,1,1,1,"all_city_parameter_inputs"))))} -> PM_emission_inventories | G19: {=IF(AND(ISBLANK(INDIRECT(ADDRESS(B19,3,1,1,"all_city_parameter_inputs"))),ISBLANK(INDIRECT(ADDRESS(B19,2,1,1,"all_city_parameter_inputs")))),"",IF(ISBLANK(INDIRECT(ADDRESS(B19,2,1,1,"all_city_parameter_inputs"))),"",INDIRECT(ADDRESS(B19,2,1,1,"all_city_parameter_inputs"))))} -> big_truck | H19: {=IF(ISBLANK(INDIRECT(ADDRESS(B19,A19,1,1,"all_city_parameter_inputs"))), "--",INDIRECT(ADDRESS(B19,A19,1,1,"all_city_parameter_inputs")))} -> 0.1924163 | I19: =IF(OR(G19="alpha",G19="beta",G19="sd",G19="mean"),"--",VLOOKUP(C19,Default!$B$5:$H$113,7,FALSE)) -> 0.45445404 | J19: =VLOOKUP(F19,Lookup!$C$5:$D$109,2, FALSE) -> Pollution values | K19: =VLOOKUP(C19,Default!$B$4:$E$113,4, FALSE) -> 0 | L19: {=IF(ISNA(VLOOKUP(D19,Grouped_Sources!$C:$C,1,FALSE)),"", INDIRECT(VLOOKUP(D19,Grouped_Sources!$C:$G,5,FALSE)))} -> air pollution and CO2 write-up_only table_V4.docx (dropbox.com)
A20: 3 | B20: 18 | C20: =IF(G20 = "",F20,IF(OR(G20="alpha",G20="beta",G20="constant",G20="sd",G20="mean",G20="sample"),F20,F20&" "&G20)) -> PM_emission_inventories truck | D20: =F20&"_"&E20 -> PM_emission_inventories_accra | E20: {=INDIRECT(ADDRESS(1,A20,1,1,"all_city_parameter_inputs"))} -> accra | F20: {=IF(AND(ISBLANK(INDIRECT(ADDRESS(B20,2,1,1,"all_city_parameter_inputs"))), ISBLANK(INDIRECT(ADDRESS(B20,1,1,1,"all_city_parameter_inputs")))), "", IF(ISBLANK(INDIRECT(ADDRESS(B20,1,1,1,"all_city_parameter_inputs"))), All_city_list!F19,INDIRECT(ADDRESS(B20,1,1,1,"all_city_parameter_inputs"))))} -> PM_emission_inventories | G20: {=IF(AND(ISBLANK(INDIRECT(ADDRESS(B20,3,1,1,"all_city_parameter_inputs"))),ISBLANK(INDIRECT(ADDRESS(B20,2,1,1,"all_city_parameter_inputs")))),"",IF(ISBLANK(INDIRECT(ADDRESS(B20,2,1,1,"all_city_parameter_inputs"))),"",INDIRECT(ADDRESS(B20,2,1,1,"all_city_parameter_inputs"))))} -> truck | H20: {=IF(ISBLANK(INDIRECT(ADDRESS(B20,A20,1,1,"all_city_parameter_inputs"))), "--",INDIRECT(ADDRESS(B20,A20,1,1,"all_city_parameter_inputs")))} -> 0.16522704 | I20: =IF(OR(G20="alpha",G20="beta",G20="sd",G20="mean"),"--",VLOOKUP(C20,Default!$B$5:$H$113,7,FALSE)) -> 0.33879567 | J20: =VLOOKUP(F20,Lookup!$C$5:$D$109,2, FALSE) -> Pollution values | K20: =VLOOKUP(C20,Default!$B$4:$E$113,4, FALSE) -> 0 | L20: {=IF(ISNA(VLOOKUP(D20,Grouped_Sources!$C:$C,1,FALSE)),"", INDIRECT(VLOOKUP(D20,Grouped_Sources!$C:$G,5,FALSE)))} -> air pollution and CO2 write-up_only table_V4.docx (dropbox.com)
A21: 3 | B21: 19 | C21: =IF(G21 = "",F21,IF(OR(G21="alpha",G21="beta",G21="constant",G21="sd",G21="mean",G21="sample"),F21,F21&" "&G21)) -> PM_emission_inventories van | D21: =F21&"_"&E21 -> PM_emission_inventories_accra | E21: {=INDIRECT(ADDRESS(1,A21,1,1,"all_city_parameter_inputs"))} -> accra | F21: {=IF(AND(ISBLANK(INDIRECT(ADDRESS(B21,2,1,1,"all_city_parameter_inputs"))), ISBLANK(INDIRECT(ADDRESS(B21,1,1,1,"all_city_parameter_inputs")))), "", IF(ISBLANK(INDIRECT(ADDRESS(B21,1,1,1,"all_city_parameter_inputs"))), All_city_list!F20,INDIRECT(ADDRESS(B21,1,1,1,"all_city_parameter_inputs"))))} -> PM_emission_inventories | G21: {=IF(AND(ISBLANK(INDIRECT(ADDRESS(B21,3,1,1,"all_city_parameter_inputs"))),ISBLANK(INDIRECT(ADDRESS(B21,2,1,1,"all_city_parameter_inputs")))),"",IF(ISBLANK(INDIRECT(ADDRESS(B21,2,1,1,"all_city_parameter_inputs"))),"",INDIRECT(ADDRESS(B21,2,1,1,"all_city_parameter_inputs"))))} -> van | H21: {=IF(ISBLANK(INDIRECT(ADDRESS(B21,A21,1,1,"all_city_parameter_inputs"))), "--",INDIRECT(ADDRESS(B21,A21,1,1,"all_city_parameter_inputs")))} -> 0 | I21: =IF(OR(G21="alpha",G21="beta",G21="sd",G21="mean"),"--",VLOOKUP(C21,Default!$B$5:$H$113,7,FALSE)) -> 0 | J21: =VLOOKUP(F21,Lookup!$C$5:$D$109,2, FALSE) -> Pollution values | K21: =VLOOKUP(C21,Default!$B$4:$E$113,4, FALSE) -> 0 | L21: {=IF(ISNA(VLOOKUP(D21,Grouped_Sources!$C:$C,1,FALSE)),"", INDIRECT(VLOOKUP(D21,Grouped_Sources!$C:$G,5,FALSE)))} -> air pollution and CO2 write-up_only table_V4.docx (dropbox.com)
A22: 3 | B22: 20 | C22: =IF(G22 = "",F22,IF(OR(G22="alpha",G22="beta",G22="constant",G22="sd",G22="mean",G22="sample"),F22,F22&" "&G22)) -> PM_emission_inventories other | D22: =F22&"_"&E22 -> PM_emission_inventories_accra | E22: {=INDIRECT(ADDRESS(1,A22,1,1,"all_city_parameter_inputs"))} -> accra | F22: {=IF(AND(ISBLANK(INDIRECT(ADDRESS(B22,2,1,1,"all_city_parameter_inputs"))), ISBLANK(INDIRECT(ADDRESS(B22,1,1,1,"all_city_parameter_inputs")))), "", IF(ISBLANK(INDIRECT(ADDRESS(B22,1,1,1,"all_city_parameter_inputs"))), All_city_list!F21,INDIRECT(ADDRESS(B22,1,1,1,"all_city_parameter_inputs"))))} -> PM_emission_inventories | G22: {=IF(AND(ISBLANK(INDIRECT(ADDRESS(B22,3,1,1,"all_city_parameter_inputs"))),ISBLANK(INDIRECT(ADDRESS(B22,2,1,1,"all_city_parameter_inputs")))),"",IF(ISBLANK(INDIRECT(ADDRESS(B22,2,1,1,"all_city_parameter_inputs"))),"",INDIRECT(ADDRESS(B22,2,1,1,"all_city_parameter_inputs"))))} -> other | H22: {=IF(ISBLANK(INDIRECT(ADDRESS(B22,A22,1,1,"all_city_parameter_inputs"))), "--",INDIRECT(ADDRESS(B22,A22,1,1,"all_city_parameter_inputs")))} -> 0 | I22: =IF(OR(G22="alpha",G22="beta",G22="sd",G22="mean"),"--",VLOOKUP(C22,Default!$B$5:$H$113,7,FALSE)) -> 0 | J22: =VLOOKUP(F22,Lookup!$C$5:$D$109,2, FALSE) -> Pollution values | K22: =VLOOKUP(C22,Default!$B$4:$E$113,4, FALSE) -> 0 | L22: {=IF(ISNA(VLOOKUP(D22,Grouped_Sources!$C:$C,1,FALSE)),"", INDIRECT(VLOOKUP(D22,Grouped_Sources!$C:$G,5,FALSE)))} -> air pollution and CO2 write-up_only table_V4.docx (dropbox.com)
A23: 3 | B23: 21 | C23: =IF(G23 = "",F23,IF(OR(G23="alpha",G23="beta",G23="constant",G23="sd",G23="mean",G23="sample"),F23,F23&" "&G23)) -> PM_emission_inventories taxi | D23: =F23&"_"&E23 -> PM_emission_inventories_accra | E23: {=INDIRECT(ADDRESS(1,A23,1,1,"all_city_parameter_inputs"))} -> accra | F23: {=IF(AND(ISBLANK(INDIRECT(ADDRESS(B23,2,1,1,"all_city_parameter_inputs"))), ISBLANK(INDIRECT(ADDRESS(B23,1,1,1,"all_city_parameter_inputs")))), "", IF(ISBLANK(INDIRECT(ADDRESS(B23,1,1,1,"all_city_parameter_inputs"))), All_city_list!F22,INDIRECT(ADDRESS(B23,1,1,1,"all_city_parameter_inputs"))))} -> PM_emission_inventories | G23: {=IF(AND(ISBLANK(INDIRECT(ADDRESS(B23,3,1,1,"all_city_parameter_inputs"))),ISBLANK(INDIRECT(ADDRESS(B23,2,1,1,"all_city_parameter_inputs")))),"",IF(ISBLANK(INDIRECT(ADDRESS(B23,2,1,1,"all_city_parameter_inputs"))),"",INDIRECT(ADDRESS(B23,2,1,1,"all_city_parameter_inputs"))))} -> taxi | H23: {=IF(ISBLANK(INDIRECT(ADDRESS(B23,A23,1,1,"all_city_parameter_inputs"))), "--",INDIRECT(ADDRESS(B23,A23,1,1,"all_city_parameter_inputs")))} -> 0 | I23: =IF(OR(G23="alpha",G23="beta",G23="sd",G23="mean"),"--",VLOOKUP(C23,Default!$B$5:$H$113,7,FALSE)) -> 0 | J23: =VLOOKUP(F23,Lookup!$C$5:$D$109,2, FALSE) -> Pollution values | K23: =VLOOKUP(C23,Default!$B$4:$E$113,4, FALSE) -> 0 | L23: {=IF(ISNA(VLOOKUP(D23,Grouped_Sources!$C:$C,1,FALSE)),"", INDIRECT(VLOOKUP(D23,Grouped_Sources!$C:$G,5,FALSE)))} -> air pollution and CO2 write-up_only table_V4.docx (dropbox.com)
A24: 3 | B24: 22 | C24: =IF(G24 = "",F24,IF(OR(G24="alpha",G24="beta",G24="constant",G24="sd",G24="mean",G24="sample"),F24,F24&" "&G24)) -> PM_emission_inventories auto_rickshaw | D24: =F24&"_"&E24 -> PM_emission_inventories_accra | E24: {=INDIRECT(ADDRESS(1,A24,1,1,"all_city_parameter_inputs"))} -> accra | F24: {=IF(AND(ISBLANK(INDIRECT(ADDRESS(B24,2,1,1,"all_city_parameter_inputs"))), ISBLANK(INDIRECT(ADDRESS(B24,1,1,1,"all_city_parameter_inputs")))), "", IF(ISBLANK(INDIRECT(ADDRESS(B24,1,1,1,"all_city_parameter_inputs"))), All_city_list!F23,INDIRECT(ADDRESS(B24,1,1,1,"all_city_parameter_inputs"))))} -> PM_emission_inventories | G24: {=IF(AND(ISBLANK(INDIRECT(ADDRESS(B24,3,1,1,"all_city_parameter_inputs"))),ISBLANK(INDIRECT(ADDRESS(B24,2,1,1,"all_city_parameter_inputs")))),"",IF(ISBLANK(INDIRECT(ADDRESS(B24,2,1,1,"all_city_parameter_inputs"))),"",INDIRECT(ADDRESS(B24,2,1,1,"all_city_parameter_inputs"))))} -> auto_rickshaw | H24: {=IF(ISBLANK(INDIRECT(ADDRESS(B24,A24,1,1,"all_city_parameter_inputs"))), "--",INDIRECT(ADDRESS(B24,A24,1,1,"all_city_parameter_inputs")))} -> 0 | I24: =IF(OR(G24="alpha",G24="beta",G24="sd",G24="mean"),"--",VLOOKUP(C24,Default!$B$5:$H$113,7,FALSE)) -> 0 | J24: =VLOOKUP(F24,Lookup!$C$5:$D$109,2, FALSE) -> Pollution values | K24: =VLOOKUP(C24,Default!$B$4:$E$113,4, FALSE) -> 0 | L24: {=IF(ISNA(VLOOKUP(D24,Grouped_Sources!$C:$C,1,FALSE)),"", INDIRECT(VLOOKUP(D24,Grouped_Sources!$C:$G,5,FALSE)))} -> air pollution and CO2 write-up_only table_V4.docx (dropbox.com)
A25: 3 | B25: 23 | C25: =IF(G25 = "",F25,IF(OR(G25="alpha",G25="beta",G25="constant",G25="sd",G25="mean",G25="sample"),F25,F25&" "&G25)) -> injury_reporting_rate | D25: =F25&"_"&E25 -> injury_reporting_rate_accra | E25: {=INDIRECT(ADDRESS(1,A25,1,1,"all_city_parameter_inputs"))} -> accra | F25: {=IF(AND(ISBLANK(INDIRECT(ADDRESS(B25,2,1,1,"all_city_parameter_inputs"))), ISBLANK(INDIRECT(ADDRESS(B25,1,1,1,"all_city_parameter_inputs")))), "", IF(ISBLANK(INDIRECT(ADDRESS(B25,1,1,1,"all_city_parameter_inputs"))), All_city_list!F24,INDIRECT(ADDRESS(B25,1,1,1,"all_city_parameter_inputs"))))} -> injury_reporting_rate | G25: {=IF(AND(ISBLANK(INDIRECT(ADDRESS(B25,3,1,1,"all_city_parameter_inputs"))),ISBLANK(INDIRECT(ADDRESS(B25,2,1,1,"all_city_parameter_inputs")))),"",IF(ISBLANK(INDIRECT(ADDRESS(B25,2,1,1,"all_city_parameter_inputs"))),"",INDIRECT(ADDRESS(B25,2,1,1,"all_city_parameter_inputs"))))} -> constant | H25: {=IF(ISBLANK(INDIRECT(ADDRESS(B25,A25,1,1,"all_city_parameter_inputs"))), "--",INDIRECT(ADDRESS(B25,A25,1,1,"all_city_parameter_inputs")))} -> 0.61011662 | I25: =IF(OR(G25="alpha",G25="beta",G25="sd",G25="mean"),"--",VLOOKUP(C25,Default!$B$5:$H$113,7,FALSE)) -> 1 | J25: =VLOOKUP(F25,Lookup!$C$5:$D$109,2, FALSE) -> Injury values | K25: =VLOOKUP(C25,Default!$B$4:$E$113,4, FALSE) -> rate at which injuries are reported | L25: InjuryReportingRate_WriteUp_vxx.docx on OneDrive Ali Abbas - ITHIM Global\Methods and Processes\Input Parameters\InjuryReportingRate
A26: 3 | B26: 24 | C26: =IF(G26 = "",F26,IF(OR(G26="alpha",G26="beta",G26="constant",G26="sd",G26="mean",G26="sample"),F26,F26&" "&G26)) -> injury_reporting_rate | D26: =F26&"_"&E26 -> injury_reporting_rate_accra | E26: {=INDIRECT(ADDRESS(1,A26,1,1,"all_city_parameter_inputs"))} -> accra | F26: {=IF(AND(ISBLANK(INDIRECT(ADDRESS(B26,2,1,1,"all_city_parameter_inputs"))), ISBLANK(INDIRECT(ADDRESS(B26,1,1,1,"all_city_parameter_inputs")))), "", IF(ISBLANK(INDIRECT(ADDRESS(B26,1,1,1,"all_city_parameter_inputs"))), All_city_list!F25,INDIRECT(ADDRESS(B26,1,1,1,"all_city_parameter_inputs"))))} -> injury_reporting_rate | G26: {=IF(AND(ISBLANK(INDIRECT(ADDRESS(B26,3,1,1,"all_city_parameter_inputs"))),ISBLANK(INDIRECT(ADDRESS(B26,2,1,1,"all_city_parameter_inputs")))),"",IF(ISBLANK(INDIRECT(ADDRESS(B26,2,1,1,"all_city_parameter_inputs"))),"",INDIRECT(ADDRESS(B26,2,1,1,"all_city_parameter_inputs"))))} -> alpha | H26: {=IF(ISBLANK(INDIRECT(ADDRESS(B26,A26,1,1,"all_city_parameter_inputs"))), "--",INDIRECT(ADDRESS(B26,A26,1,1,"all_city_parameter_inputs")))} -> 3.0181604 | I26: =IF(OR(G26="alpha",G26="beta",G26="sd",G26="mean"),"--",VLOOKUP(C26,Default!$B$5:$H$113,7,FALSE)) -> -- | J26: =VLOOKUP(F26,Lookup!$C$5:$D$109,2, FALSE) -> Injury values | K26: =VLOOKUP(C26,Default!$B$4:$E$113,4, FALSE) -> rate at which injuries are reported | L26: {=IF(ISNA(VLOOKUP(D26,Grouped_Sources!$C:$C,1,FALSE)),"", INDIRECT(VLOOKUP(D26,Grouped_Sources!$C:$G,5,FALSE)))} -> InjuryReportingRate_WriteUp_vxx.docx on OneDrive Ali Abbas - ITHIM Global\Methods and Processes\Input Parameters\InjuryReportingRate
A27: 3 | B27: 25 | C27: =IF(G27 = "",F27,IF(OR(G27="alpha",G27="beta",G27="constant",G27="sd",G27="mean",G27="sample"),F27,F27&" "&G27)) -> injury_reporting_rate | D27: =F27&"_"&E27 -> injury_reporting_rate_accra | E27: {=INDIRECT(ADDRESS(1,A27,1,1,"all_city_parameter_inputs"))} -> accra | F27: {=IF(AND(ISBLANK(INDIRECT(ADDRESS(B27,2,1,1,"all_city_parameter_inputs"))), ISBLANK(INDIRECT(ADDRESS(B27,1,1,1,"all_city_parameter_inputs")))), "", IF(ISBLANK(INDIRECT(ADDRESS(B27,1,1,1,"all_city_parameter_inputs"))), All_city_list!F26,INDIRECT(ADDRESS(B27,1,1,1,"all_city_parameter_inputs"))))} -> injury_reporting_rate | G27: {=IF(AND(ISBLANK(INDIRECT(ADDRESS(B27,3,1,1,"all_city_parameter_inputs"))),ISBLANK(INDIRECT(ADDRESS(B27,2,1,1,"all_city_parameter_inputs")))),"",IF(ISBLANK(INDIRECT(ADDRESS(B27,2,1,1,"all_city_parameter_inputs"))),"",INDIRECT(ADDRESS(B27,2,1,1,"all_city_parameter_inputs"))))} -> beta | H27: {=IF(ISBLANK(INDIRECT(ADDRESS(B27,A27,1,1,"all_city_parameter_inputs"))), "--",INDIRECT(ADDRESS(B27,A27,1,1,"all_city_parameter_inputs")))} -> 1.9286978 | I27: =IF(OR(G27="alpha",G27="beta",G27="sd",G27="mean"),"--",VLOOKUP(C27,Default!$B$5:$H$113,7,FALSE)) -> -- | J27: =VLOOKUP(F27,Lookup!$C$5:$D$109,2, FALSE) -> Injury values | K27: =VLOOKUP(C27,Default!$B$4:$E$113,4, FALSE) -> rate at which injuries are reported | L27: {=IF(ISNA(VLOOKUP(D27,Grouped_Sources!$C:$C,1,FALSE)),"", INDIRECT(VLOOKUP(D27,Grouped_Sources!$C:$G,5,FALSE)))} -> InjuryReportingRate_WriteUp_vxx.docx on OneDrive Ali Abbas - ITHIM Global\Methods and Processes\Input Parameters\InjuryReportingRate
A28: 3 | B28: 26 | C28: =IF(G28 = "",F28,IF(OR(G28="alpha",G28="beta",G28="constant",G28="sd",G28="mean",G28="sample"),F28,F28&" "&G28)) -> chronic_disease_scalar | D28: =F28&"_"&E28 -> chronic_disease_scalar_accra | E28: {=INDIRECT(ADDRESS(1,A28,1,1,"all_city_parameter_inputs"))} -> accra | F28: {=IF(AND(ISBLANK(INDIRECT(ADDRESS(B28,2,1,1,"all_city_parameter_inputs"))), ISBLANK(INDIRECT(ADDRESS(B28,1,1,1,"all_city_parameter_inputs")))), "", IF(ISBLANK(INDIRECT(ADDRESS(B28,1,1,1,"all_city_parameter_inputs"))), All_city_list!F27,INDIRECT(ADDRESS(B28,1,1,1,"all_city_parameter_inputs"))))} -> chronic_disease_scalar | G28: {=IF(AND(ISBLANK(INDIRECT(ADDRESS(B28,3,1,1,"all_city_parameter_inputs"))),ISBLANK(INDIRECT(ADDRESS(B28,2,1,1,"all_city_parameter_inputs")))),"",IF(ISBLANK(INDIRECT(ADDRESS(B28,2,1,1,"all_city_parameter_inputs"))),"",INDIRECT(ADDRESS(B28,2,1,1,"all_city_parameter_inputs"))))} -> constant | H28: {=IF(ISBLANK(INDIRECT(ADDRESS(B28,A28,1,1,"all_city_parameter_inputs"))), "--",INDIRECT(ADDRESS(B28,A28,1,1,"all_city_parameter_inputs")))} -> 1 | I28: =IF(OR(G28="alpha",G28="beta",G28="sd",G28="mean"),"--",VLOOKUP(C28,Default!$B$5:$H$113,7,FALSE)) -> 1 | J28: =VLOOKUP(F28,Lookup!$C$5:$D$109,2, FALSE) -> Health values | K28: =VLOOKUP(C28,Default!$B$4:$E$113,4, FALSE) -> scalar for GBD data | L28: dummy value - leave for time being
A29: 3 | B29: 27 | C29: =IF(G29 = "",F29,IF(OR(G29="alpha",G29="beta",G29="constant",G29="sd",G29="mean",G29="sample"),F29,F29&" "&G29)) -> chronic_disease_scalar | D29: =F29&"_"&E29 -> chronic_disease_scalar_accra | E29: {=INDIRECT(ADDRESS(1,A29,1,1,"all_city_parameter_inputs"))} -> accra | F29: {=IF(AND(ISBLANK(INDIRECT(ADDRESS(B29,2,1,1,"all_city_parameter_inputs"))), ISBLANK(INDIRECT(ADDRESS(B29,1,1,1,"all_city_parameter_inputs")))), "", IF(ISBLANK(INDIRECT(ADDRESS(B29,1,1,1,"all_city_parameter_inputs"))), All_city_list!F28,INDIRECT(ADDRESS(B29,1,1,1,"all_city_parameter_inputs"))))} -> chronic_disease_scalar | G29: {=IF(AND(ISBLANK(INDIRECT(ADDRESS(B29,3,1,1,"all_city_parameter_inputs"))),ISBLANK(INDIRECT(ADDRESS(B29,2,1,1,"all_city_parameter_inputs")))),"",IF(ISBLANK(INDIRECT(ADDRESS(B29,2,1,1,"all_city_parameter_inputs"))),"",INDIRECT(ADDRESS(B29,2,1,1,"all_city_parameter_inputs"))))} -> mean | H29: {=IF(ISBLANK(INDIRECT(ADDRESS(B29,A29,1,1,"all_city_parameter_inputs"))), "--",INDIRECT(ADDRESS(B29,A29,1,1,"all_city_parameter_inputs")))} -> 1 | I29: =IF(OR(G29="alpha",G29="beta",G29="sd",G29="mean"),"--",VLOOKUP(C29,Default!$B$5:$H$113,7,FALSE)) -> -- | J29: =VLOOKUP(F29,Lookup!$C$5:$D$109,2, FALSE) -> Health values | K29: =VLOOKUP(C29,Default!$B$4:$E$113,4, FALSE) -> scalar for GBD data | L29: {=IF(ISNA(VLOOKUP(D29,Grouped_Sources!$C:$C,1,FALSE)),"", INDIRECT(VLOOKUP(D29,Grouped_Sources!$C:$G,5,FALSE)))} -> dummy value - leave for time being
A30: 3 | B30: 28 | C30: =IF(G30 = "",F30,IF(OR(G30="alpha",G30="beta",G30="constant",G30="sd",G30="mean",G30="sample"),F30,F30&" "&G30)) -> chronic_disease_scalar | D30: =F30&"_"&E30 -> chronic_disease_scalar_accra | E30: {=INDIRECT(ADDRESS(1,A30,1,1,"all_city_parameter_inputs"))} -> accra | F30: {=IF(AND(ISBLANK(INDIRECT(ADDRESS(B30,2,1,1,"all_city_parameter_inputs"))), ISBLANK(INDIRECT(ADDRESS(B30,1,1,1,"all_city_parameter_inputs")))), "", IF(ISBLANK(INDIRECT(ADDRESS(B30,1,1,1,"all_city_parameter_inputs"))), All_city_list!F29,INDIRECT(ADDRESS(B30,1,1,1,"all_city_parameter_inputs"))))} -> chronic_disease_scalar | G30: {=IF(AND(ISBLANK(INDIRECT(ADDRESS(B30,3,1,1,"all_city_parameter_inputs"))),ISBLANK(INDIRECT(ADDRESS(B30,2,1,1,"all_city_parameter_inputs")))),"",IF(ISBLANK(INDIRECT(ADDRESS(B30,2,1,1,"all_city_parameter_inputs"))),"",INDIRECT(ADDRESS(B30,2,1,1,"all_city_parameter_inputs"))))} -> sd | H30: {=IF(ISBLANK(INDIRECT(ADDRESS(B30,A30,1,1,"all_city_parameter_inputs"))), "--",INDIRECT(ADDRESS(B30,A30,1,1,"all_city_parameter_inputs")))} -> 1.2 | I30: =IF(OR(G30="alpha",G30="beta",G30="sd",G30="mean"),"--",VLOOKUP(C30,Default!$B$5:$H$113,7,FALSE)) -> -- | J30: =VLOOKUP(F30,Lookup!$C$5:$D$109,2, FALSE) -> Health values | K30: =VLOOKUP(C30,Default!$B$4:$E$113,4, FALSE) -> scalar for GBD data | L30: {=IF(ISNA(VLOOKUP(D30,Grouped_Sources!$C:$C,1,FALSE)),"", INDIRECT(VLOOKUP(D30,Grouped_Sources!$C:$G,5,FALSE)))} -> dummy value - leave for time being
